*** Starting uWSGI 2.0.18 (64bit) on [Wed Apr  8 01:21:34 2020] ***
compiled with version: 7.5.0 on 07 April 2020 23:31:59
os: Linux-5.0.0-38-generic #41-Ubuntu SMP Tue Dec 3 00:27:35 UTC 2019
nodename: 7846819b8405
machine: x86_64
clock source: unix
detected number of CPU cores: 12
current working directory: /nb/webroot
detected binary path: /usr/local/bin/uwsgi
!!! no internal routing support, rebuild with pcre support !!!
uWSGI running as root, you can use --uid/--gid/--chroot options
*** WARNING: you are running uWSGI as root !!! (use the --uid flag) *** 
*** WARNING: you are running uWSGI without its master process manager ***
your memory page size is 4096 bytes
detected max file descriptor number: 1048576
lock engine: pthread robust mutexes
thunder lock: disabled (you can enable it with --thunder-lock)
uwsgi socket 0 bound to TCP address 0.0.0.0:9201 fd 3
uWSGI running as root, you can use --uid/--gid/--chroot options
*** WARNING: you are running uWSGI as root !!! (use the --uid flag) *** 
Python version: 3.6.9 (default, Nov  7 2019, 10:44:02)  [GCC 8.3.0]
*** Python threads support is disabled. You can enable it with --enable-threads ***
Python main interpreter initialized at 0x55de3e195240
uWSGI running as root, you can use --uid/--gid/--chroot options
*** WARNING: you are running uWSGI as root !!! (use the --uid flag) *** 
your server socket listen backlog is limited to 100 connections
your mercy for graceful operations on workers is 60 seconds
mapped 72904 bytes (71 KB) for 1 cores
*** Operational MODE: single process ***
WSGI app 0 (mountpoint='') ready in 0 seconds on interpreter 0x55de3e195240 pid: 1 (default app)
uWSGI running as root, you can use --uid/--gid/--chroot options
*** WARNING: you are running uWSGI as root !!! (use the --uid flag) *** 
*** uWSGI is running in multiple interpreter mode ***
spawned uWSGI worker 1 (and the only) (pid: 1, cores: 1)
[pid: 1|app: 0|req: 1/1] 192.168.10.50 () {44 vars in 928 bytes} [Wed Apr  8 01:21:45 2020] GET / => generated 3407 bytes in 106 msecs (HTTP/1.1 200) 1 headers in 44 bytes (1 switches on core 0)
[pid: 1|app: 0|req: 2/2] 192.168.10.50 () {46 vars in 894 bytes} [Wed Apr  8 01:21:45 2020] GET /favicon.ico => generated 2154 bytes in 7 msecs (HTTP/1.1 200) 1 headers in 44 bytes (1 switches on core 0)
[pid: 1|app: 0|req: 3/3] 192.168.10.50 () {44 vars in 928 bytes} [Wed Apr  8 01:21:45 2020] GET / => generated 3407 bytes in 12 msecs (HTTP/1.1 200) 1 headers in 44 bytes (1 switches on core 0)
[pid: 1|app: 0|req: 4/4] 192.168.10.50 () {46 vars in 894 bytes} [Wed Apr  8 01:21:46 2020] GET /favicon.ico => generated 2154 bytes in 6 msecs (HTTP/1.1 200) 1 headers in 44 bytes (1 switches on core 0)
[pid: 1|app: 0|req: 5/5] 192.168.10.50 () {44 vars in 928 bytes} [Wed Apr  8 01:21:46 2020] GET / => generated 3407 bytes in 13 msecs (HTTP/1.1 200) 1 headers in 44 bytes (1 switches on core 0)
[pid: 1|app: 0|req: 6/6] 192.168.10.50 () {46 vars in 894 bytes} [Wed Apr  8 01:21:46 2020] GET /favicon.ico => generated 2154 bytes in 6 msecs (HTTP/1.1 200) 1 headers in 44 bytes (1 switches on core 0)
[pid: 1|app: 0|req: 7/7] 192.168.10.50 () {44 vars in 928 bytes} [Wed Apr  8 01:21:46 2020] GET / => generated 3407 bytes in 10 msecs (HTTP/1.1 200) 1 headers in 44 bytes (1 switches on core 0)
[pid: 1|app: 0|req: 8/8] 192.168.10.50 () {46 vars in 894 bytes} [Wed Apr  8 01:21:46 2020] GET /favicon.ico => generated 2154 bytes in 6 msecs (HTTP/1.1 200) 1 headers in 44 bytes (1 switches on core 0)
[pid: 1|app: 0|req: 9/9] 192.168.10.50 () {44 vars in 928 bytes} [Wed Apr  8 01:21:46 2020] GET / => generated 3407 bytes in 13 msecs (HTTP/1.1 200) 1 headers in 44 bytes (1 switches on core 0)
[pid: 1|app: 0|req: 10/10] 192.168.10.50 () {46 vars in 894 bytes} [Wed Apr  8 01:21:46 2020] GET /favicon.ico => generated 2154 bytes in 6 msecs (HTTP/1.1 200) 1 headers in 44 bytes (1 switches on core 0)
[pid: 1|app: 0|req: 11/11] 192.168.10.50 () {44 vars in 928 bytes} [Wed Apr  8 01:21:46 2020] GET / => generated 3407 bytes in 11 msecs (HTTP/1.1 200) 1 headers in 44 bytes (1 switches on core 0)
[pid: 1|app: 0|req: 12/12] 192.168.10.50 () {46 vars in 894 bytes} [Wed Apr  8 01:21:46 2020] GET /favicon.ico => generated 2154 bytes in 6 msecs (HTTP/1.1 200) 1 headers in 44 bytes (1 switches on core 0)
[pid: 1|app: 0|req: 13/13] 192.168.10.50 () {44 vars in 928 bytes} [Wed Apr  8 01:21:47 2020] GET / => generated 3407 bytes in 10 msecs (HTTP/1.1 200) 1 headers in 44 bytes (1 switches on core 0)
[pid: 1|app: 0|req: 14/14] 192.168.10.50 () {46 vars in 894 bytes} [Wed Apr  8 01:21:47 2020] GET /favicon.ico => generated 2154 bytes in 6 msecs (HTTP/1.1 200) 1 headers in 44 bytes (1 switches on core 0)
[pid: 1|app: 0|req: 15/15] 192.168.10.50 () {44 vars in 928 bytes} [Wed Apr  8 01:21:48 2020] GET / => generated 3407 bytes in 11 msecs (HTTP/1.1 200) 1 headers in 44 bytes (1 switches on core 0)
[pid: 1|app: 0|req: 16/16] 192.168.10.50 () {46 vars in 894 bytes} [Wed Apr  8 01:21:48 2020] GET /favicon.ico => generated 2154 bytes in 6 msecs (HTTP/1.1 200) 1 headers in 44 bytes (1 switches on core 0)
[pid: 1|app: 0|req: 17/17] 192.168.10.50 () {44 vars in 928 bytes} [Wed Apr  8 01:21:49 2020] GET / => generated 3407 bytes in 10 msecs (HTTP/1.1 200) 1 headers in 44 bytes (1 switches on core 0)
[pid: 1|app: 0|req: 18/18] 192.168.10.50 () {46 vars in 894 bytes} [Wed Apr  8 01:21:49 2020] GET /favicon.ico => generated 2154 bytes in 6 msecs (HTTP/1.1 200) 1 headers in 44 bytes (1 switches on core 0)
[pid: 1|app: 0|req: 19/19] 192.168.10.50 () {44 vars in 928 bytes} [Wed Apr  8 01:21:49 2020] GET / => generated 3407 bytes in 12 msecs (HTTP/1.1 200) 1 headers in 44 bytes (1 switches on core 0)
[pid: 1|app: 0|req: 20/20] 192.168.10.50 () {46 vars in 894 bytes} [Wed Apr  8 01:21:49 2020] GET /favicon.ico => generated 2154 bytes in 6 msecs (HTTP/1.1 200) 1 headers in 44 bytes (1 switches on core 0)
*** Starting uWSGI 2.0.18 (64bit) on [Wed Apr  8 01:30:39 2020] ***
compiled with version: 7.5.0 on 07 April 2020 23:31:59
os: Linux-5.0.0-38-generic #41-Ubuntu SMP Tue Dec 3 00:27:35 UTC 2019
nodename: b6bbd1b85e08
machine: x86_64
clock source: unix
detected number of CPU cores: 12
current working directory: /nb/webroot
detected binary path: /usr/local/bin/uwsgi
!!! no internal routing support, rebuild with pcre support !!!
uWSGI running as root, you can use --uid/--gid/--chroot options
*** WARNING: you are running uWSGI as root !!! (use the --uid flag) *** 
*** WARNING: you are running uWSGI without its master process manager ***
your memory page size is 4096 bytes
detected max file descriptor number: 1048576
lock engine: pthread robust mutexes
thunder lock: disabled (you can enable it with --thunder-lock)
uwsgi socket 0 bound to TCP address 0.0.0.0:9201 fd 3
uWSGI running as root, you can use --uid/--gid/--chroot options
*** WARNING: you are running uWSGI as root !!! (use the --uid flag) *** 
Python version: 3.6.9 (default, Nov  7 2019, 10:44:02)  [GCC 8.3.0]
*** Python threads support is disabled. You can enable it with --enable-threads ***
Python main interpreter initialized at 0x5625e43d8240
uWSGI running as root, you can use --uid/--gid/--chroot options
*** WARNING: you are running uWSGI as root !!! (use the --uid flag) *** 
your server socket listen backlog is limited to 100 connections
your mercy for graceful operations on workers is 60 seconds
mapped 72904 bytes (71 KB) for 1 cores
*** Operational MODE: single process ***
WSGI app 0 (mountpoint='') ready in 0 seconds on interpreter 0x5625e43d8240 pid: 1 (default app)
uWSGI running as root, you can use --uid/--gid/--chroot options
*** WARNING: you are running uWSGI as root !!! (use the --uid flag) *** 
*** uWSGI is running in multiple interpreter mode ***
spawned uWSGI worker 1 (and the only) (pid: 1, cores: 1)
[pid: 1|app: 0|req: 1/1] 192.168.10.50 () {44 vars in 928 bytes} [Wed Apr  8 01:38:41 2020] GET / => generated 3407 bytes in 32 msecs (HTTP/1.1 200) 1 headers in 44 bytes (1 switches on core 0)
[pid: 1|app: 0|req: 2/2] 192.168.10.50 () {46 vars in 894 bytes} [Wed Apr  8 01:38:41 2020] GET /favicon.ico => generated 2154 bytes in 7 msecs (HTTP/1.1 200) 1 headers in 44 bytes (1 switches on core 0)
*** Starting uWSGI 2.0.18 (64bit) on [Wed Apr  8 01:59:35 2020] ***
compiled with version: 7.5.0 on 07 April 2020 23:31:59
os: Linux-5.0.0-38-generic #41-Ubuntu SMP Tue Dec 3 00:27:35 UTC 2019
nodename: 492fde935305
machine: x86_64
clock source: unix
detected number of CPU cores: 12
current working directory: /nb/webroot
detected binary path: /usr/local/bin/uwsgi
!!! no internal routing support, rebuild with pcre support !!!
uWSGI running as root, you can use --uid/--gid/--chroot options
*** WARNING: you are running uWSGI as root !!! (use the --uid flag) *** 
*** WARNING: you are running uWSGI without its master process manager ***
your memory page size is 4096 bytes
detected max file descriptor number: 1048576
lock engine: pthread robust mutexes
thunder lock: disabled (you can enable it with --thunder-lock)
uwsgi socket 0 bound to TCP address 0.0.0.0:9201 fd 3
uWSGI running as root, you can use --uid/--gid/--chroot options
*** WARNING: you are running uWSGI as root !!! (use the --uid flag) *** 
Python version: 3.6.9 (default, Nov  7 2019, 10:44:02)  [GCC 8.3.0]
*** Python threads support is disabled. You can enable it with --enable-threads ***
Python main interpreter initialized at 0x558656814240
uWSGI running as root, you can use --uid/--gid/--chroot options
*** WARNING: you are running uWSGI as root !!! (use the --uid flag) *** 
your server socket listen backlog is limited to 100 connections
your mercy for graceful operations on workers is 60 seconds
mapped 72904 bytes (71 KB) for 1 cores
*** Operational MODE: single process ***
WSGI app 0 (mountpoint='') ready in 0 seconds on interpreter 0x558656814240 pid: 1 (default app)
uWSGI running as root, you can use --uid/--gid/--chroot options
*** WARNING: you are running uWSGI as root !!! (use the --uid flag) *** 
*** uWSGI is running in multiple interpreter mode ***
spawned uWSGI worker 1 (and the only) (pid: 1, cores: 1)
Traceback (most recent call last):
  File "/usr/local/lib/python3.6/dist-packages/pymysql/connections.py", line 583, in connect
    **kwargs)
  File "/usr/lib/python3.6/socket.py", line 724, in create_connection
    raise err
  File "/usr/lib/python3.6/socket.py", line 713, in create_connection
    sock.connect(sa)
ConnectionRefusedError: [Errno 111] Connection refused

During handling of the above exception, another exception occurred:

Traceback (most recent call last):
  File "./index.py", line 20, in application
    init.mysql.connected(init.config['MYSQL']['host'],init.config['MYSQL']['port'],init.config['MYSQL']['database'],init.config['MYSQL']['user'],init.config['MYSQL']['password'])
  File "../lib/MySQLProvider.py", line 10, in connected
    self.connect = pymysql.connect(host=host,user=user,password=password,db=database,port=int(port))
  File "/usr/local/lib/python3.6/dist-packages/pymysql/__init__.py", line 94, in Connect
    return Connection(*args, **kwargs)
  File "/usr/local/lib/python3.6/dist-packages/pymysql/connections.py", line 325, in __init__
    self.connect()
  File "/usr/local/lib/python3.6/dist-packages/pymysql/connections.py", line 630, in connect
    raise exc
pymysql.err.OperationalError: (2003, "Can't connect to MySQL server on 'db' ([Errno 111] Connection refused)")
[pid: 1|app: 0|req: 1/1] 192.168.10.50 () {44 vars in 928 bytes} [Wed Apr  8 01:59:50 2020] GET / => generated 0 bytes in 9 msecs (HTTP/1.1 500) 0 headers in 0 bytes (0 switches on core 0)
Traceback (most recent call last):
  File "/usr/local/lib/python3.6/dist-packages/pymysql/connections.py", line 583, in connect
    **kwargs)
  File "/usr/lib/python3.6/socket.py", line 724, in create_connection
    raise err
  File "/usr/lib/python3.6/socket.py", line 713, in create_connection
    sock.connect(sa)
ConnectionRefusedError: [Errno 111] Connection refused

During handling of the above exception, another exception occurred:

Traceback (most recent call last):
  File "./index.py", line 20, in application
    init.mysql.connected(init.config['MYSQL']['host'],init.config['MYSQL']['port'],init.config['MYSQL']['database'],init.config['MYSQL']['user'],init.config['MYSQL']['password'])
  File "../lib/MySQLProvider.py", line 10, in connected
    self.connect = pymysql.connect(host=host,user=user,password=password,db=database,port=int(port))
  File "/usr/local/lib/python3.6/dist-packages/pymysql/__init__.py", line 94, in Connect
    return Connection(*args, **kwargs)
  File "/usr/local/lib/python3.6/dist-packages/pymysql/connections.py", line 325, in __init__
    self.connect()
  File "/usr/local/lib/python3.6/dist-packages/pymysql/connections.py", line 630, in connect
    raise exc
pymysql.err.OperationalError: (2003, "Can't connect to MySQL server on 'db' ([Errno 111] Connection refused)")
[pid: 1|app: 0|req: 2/2] 192.168.10.50 () {46 vars in 894 bytes} [Wed Apr  8 01:59:50 2020] GET /favicon.ico => generated 0 bytes in 4 msecs (HTTP/1.1 500) 0 headers in 0 bytes (0 switches on core 0)
Traceback (most recent call last):
  File "/usr/local/lib/python3.6/dist-packages/pymysql/connections.py", line 583, in connect
    **kwargs)
  File "/usr/lib/python3.6/socket.py", line 724, in create_connection
    raise err
  File "/usr/lib/python3.6/socket.py", line 713, in create_connection
    sock.connect(sa)
ConnectionRefusedError: [Errno 111] Connection refused

During handling of the above exception, another exception occurred:

Traceback (most recent call last):
  File "./index.py", line 20, in application
    init.mysql.connected(init.config['MYSQL']['host'],init.config['MYSQL']['port'],init.config['MYSQL']['database'],init.config['MYSQL']['user'],init.config['MYSQL']['password'])
  File "../lib/MySQLProvider.py", line 10, in connected
    self.connect = pymysql.connect(host=host,user=user,password=password,db=database,port=int(port))
  File "/usr/local/lib/python3.6/dist-packages/pymysql/__init__.py", line 94, in Connect
    return Connection(*args, **kwargs)
  File "/usr/local/lib/python3.6/dist-packages/pymysql/connections.py", line 325, in __init__
    self.connect()
  File "/usr/local/lib/python3.6/dist-packages/pymysql/connections.py", line 630, in connect
    raise exc
pymysql.err.OperationalError: (2003, "Can't connect to MySQL server on 'db' ([Errno 111] Connection refused)")
[pid: 1|app: 0|req: 3/3] 192.168.10.50 () {44 vars in 928 bytes} [Wed Apr  8 01:59:51 2020] GET / => generated 0 bytes in 4 msecs (HTTP/1.1 500) 0 headers in 0 bytes (0 switches on core 0)
Traceback (most recent call last):
  File "/usr/local/lib/python3.6/dist-packages/pymysql/connections.py", line 583, in connect
    **kwargs)
  File "/usr/lib/python3.6/socket.py", line 724, in create_connection
    raise err
  File "/usr/lib/python3.6/socket.py", line 713, in create_connection
    sock.connect(sa)
ConnectionRefusedError: [Errno 111] Connection refused

During handling of the above exception, another exception occurred:

Traceback (most recent call last):
  File "./index.py", line 20, in application
    init.mysql.connected(init.config['MYSQL']['host'],init.config['MYSQL']['port'],init.config['MYSQL']['database'],init.config['MYSQL']['user'],init.config['MYSQL']['password'])
  File "../lib/MySQLProvider.py", line 10, in connected
    self.connect = pymysql.connect(host=host,user=user,password=password,db=database,port=int(port))
  File "/usr/local/lib/python3.6/dist-packages/pymysql/__init__.py", line 94, in Connect
    return Connection(*args, **kwargs)
  File "/usr/local/lib/python3.6/dist-packages/pymysql/connections.py", line 325, in __init__
    self.connect()
  File "/usr/local/lib/python3.6/dist-packages/pymysql/connections.py", line 630, in connect
    raise exc
pymysql.err.OperationalError: (2003, "Can't connect to MySQL server on 'db' ([Errno 111] Connection refused)")
[pid: 1|app: 0|req: 4/4] 192.168.10.50 () {46 vars in 894 bytes} [Wed Apr  8 01:59:51 2020] GET /favicon.ico => generated 0 bytes in 4 msecs (HTTP/1.1 500) 0 headers in 0 bytes (0 switches on core 0)
[pid: 1|app: 0|req: 5/5] 192.168.10.50 () {44 vars in 928 bytes} [Wed Apr  8 02:00:03 2020] GET / => generated 3407 bytes in 105 msecs (HTTP/1.1 200) 1 headers in 44 bytes (1 switches on core 0)
[pid: 1|app: 0|req: 6/6] 192.168.10.50 () {46 vars in 894 bytes} [Wed Apr  8 02:00:03 2020] GET /favicon.ico => generated 2154 bytes in 7 msecs (HTTP/1.1 200) 1 headers in 44 bytes (1 switches on core 0)
*** Starting uWSGI 2.0.18 (64bit) on [Wed Apr  8 02:13:27 2020] ***
compiled with version: 7.5.0 on 07 April 2020 23:31:59
os: Linux-5.0.0-38-generic #41-Ubuntu SMP Tue Dec 3 00:27:35 UTC 2019
nodename: 541e2ebf3294
machine: x86_64
clock source: unix
detected number of CPU cores: 12
current working directory: /nb/webroot
detected binary path: /usr/local/bin/uwsgi
!!! no internal routing support, rebuild with pcre support !!!
uWSGI running as root, you can use --uid/--gid/--chroot options
*** WARNING: you are running uWSGI as root !!! (use the --uid flag) *** 
*** WARNING: you are running uWSGI without its master process manager ***
your memory page size is 4096 bytes
detected max file descriptor number: 1048576
lock engine: pthread robust mutexes
thunder lock: disabled (you can enable it with --thunder-lock)
uwsgi socket 0 bound to TCP address 0.0.0.0:9201 fd 3
uWSGI running as root, you can use --uid/--gid/--chroot options
*** WARNING: you are running uWSGI as root !!! (use the --uid flag) *** 
Python version: 3.6.9 (default, Nov  7 2019, 10:44:02)  [GCC 8.3.0]
*** Python threads support is disabled. You can enable it with --enable-threads ***
Python main interpreter initialized at 0x55b80779a240
uWSGI running as root, you can use --uid/--gid/--chroot options
*** WARNING: you are running uWSGI as root !!! (use the --uid flag) *** 
your server socket listen backlog is limited to 100 connections
your mercy for graceful operations on workers is 60 seconds
mapped 72904 bytes (71 KB) for 1 cores
*** Operational MODE: single process ***
WSGI app 0 (mountpoint='') ready in 0 seconds on interpreter 0x55b80779a240 pid: 1 (default app)
uWSGI running as root, you can use --uid/--gid/--chroot options
*** WARNING: you are running uWSGI as root !!! (use the --uid flag) *** 
*** uWSGI is running in multiple interpreter mode ***
spawned uWSGI worker 1 (and the only) (pid: 1, cores: 1)
[pid: 1|app: 0|req: 1/1] 192.168.10.50 () {44 vars in 928 bytes} [Wed Apr  8 02:14:01 2020] GET / => generated 3407 bytes in 97 msecs (HTTP/1.1 200) 1 headers in 44 bytes (1 switches on core 0)
[pid: 1|app: 0|req: 2/2] 192.168.10.50 () {46 vars in 894 bytes} [Wed Apr  8 02:14:01 2020] GET /favicon.ico => generated 2154 bytes in 7 msecs (HTTP/1.1 200) 1 headers in 44 bytes (1 switches on core 0)
[pid: 1|app: 0|req: 3/3] 192.168.10.50 () {44 vars in 928 bytes} [Wed Apr  8 02:14:01 2020] GET / => generated 3407 bytes in 14 msecs (HTTP/1.1 200) 1 headers in 44 bytes (1 switches on core 0)
[pid: 1|app: 0|req: 4/4] 192.168.10.50 () {46 vars in 894 bytes} [Wed Apr  8 02:14:01 2020] GET /favicon.ico => generated 2154 bytes in 6 msecs (HTTP/1.1 200) 1 headers in 44 bytes (1 switches on core 0)
[pid: 1|app: 0|req: 5/5] 192.168.10.50 () {44 vars in 928 bytes} [Wed Apr  8 02:14:02 2020] GET / => generated 3407 bytes in 14 msecs (HTTP/1.1 200) 1 headers in 44 bytes (1 switches on core 0)
[pid: 1|app: 0|req: 6/6] 192.168.10.50 () {46 vars in 894 bytes} [Wed Apr  8 02:14:02 2020] GET /favicon.ico => generated 2154 bytes in 6 msecs (HTTP/1.1 200) 1 headers in 44 bytes (1 switches on core 0)
*** Starting uWSGI 2.0.18 (64bit) on [Wed Apr  8 02:18:44 2020] ***
compiled with version: 7.5.0 on 07 April 2020 23:31:59
os: Linux-5.0.0-38-generic #41-Ubuntu SMP Tue Dec 3 00:27:35 UTC 2019
nodename: 89583f7261b8
machine: x86_64
clock source: unix
detected number of CPU cores: 12
current working directory: /nb/webroot
detected binary path: /usr/local/bin/uwsgi
!!! no internal routing support, rebuild with pcre support !!!
uWSGI running as root, you can use --uid/--gid/--chroot options
*** WARNING: you are running uWSGI as root !!! (use the --uid flag) *** 
*** WARNING: you are running uWSGI without its master process manager ***
your memory page size is 4096 bytes
detected max file descriptor number: 1048576
lock engine: pthread robust mutexes
thunder lock: disabled (you can enable it with --thunder-lock)
uwsgi socket 0 bound to TCP address 0.0.0.0:9201 fd 3
uWSGI running as root, you can use --uid/--gid/--chroot options
*** WARNING: you are running uWSGI as root !!! (use the --uid flag) *** 
Python version: 3.6.9 (default, Nov  7 2019, 10:44:02)  [GCC 8.3.0]
*** Python threads support is disabled. You can enable it with --enable-threads ***
Python main interpreter initialized at 0x55eed1c06240
uWSGI running as root, you can use --uid/--gid/--chroot options
*** WARNING: you are running uWSGI as root !!! (use the --uid flag) *** 
your server socket listen backlog is limited to 100 connections
your mercy for graceful operations on workers is 60 seconds
mapped 72904 bytes (71 KB) for 1 cores
*** Operational MODE: single process ***
WSGI app 0 (mountpoint='') ready in 0 seconds on interpreter 0x55eed1c06240 pid: 1 (default app)
uWSGI running as root, you can use --uid/--gid/--chroot options
*** WARNING: you are running uWSGI as root !!! (use the --uid flag) *** 
*** uWSGI is running in multiple interpreter mode ***
spawned uWSGI worker 1 (and the only) (pid: 1, cores: 1)
Traceback (most recent call last):
  File "/usr/local/lib/python3.6/dist-packages/pymysql/connections.py", line 583, in connect
    **kwargs)
  File "/usr/lib/python3.6/socket.py", line 724, in create_connection
    raise err
  File "/usr/lib/python3.6/socket.py", line 713, in create_connection
    sock.connect(sa)
ConnectionRefusedError: [Errno 111] Connection refused

During handling of the above exception, another exception occurred:

Traceback (most recent call last):
  File "./index.py", line 20, in application
    init.mysql.connected(init.config['MYSQL']['host'],init.config['MYSQL']['port'],init.config['MYSQL']['database'],init.config['MYSQL']['user'],init.config['MYSQL']['password'])
  File "../lib/MySQLProvider.py", line 10, in connected
    self.connect = pymysql.connect(host=host,user=user,password=password,db=database,port=int(port))
  File "/usr/local/lib/python3.6/dist-packages/pymysql/__init__.py", line 94, in Connect
    return Connection(*args, **kwargs)
  File "/usr/local/lib/python3.6/dist-packages/pymysql/connections.py", line 325, in __init__
    self.connect()
  File "/usr/local/lib/python3.6/dist-packages/pymysql/connections.py", line 630, in connect
    raise exc
pymysql.err.OperationalError: (2003, "Can't connect to MySQL server on 'db' ([Errno 111] Connection refused)")
[pid: 1|app: 0|req: 1/1] 192.168.10.50 () {44 vars in 928 bytes} [Wed Apr  8 02:18:56 2020] GET / => generated 0 bytes in 17 msecs (HTTP/1.1 500) 0 headers in 0 bytes (0 switches on core 0)
Traceback (most recent call last):
  File "/usr/local/lib/python3.6/dist-packages/pymysql/connections.py", line 583, in connect
    **kwargs)
  File "/usr/lib/python3.6/socket.py", line 724, in create_connection
    raise err
  File "/usr/lib/python3.6/socket.py", line 713, in create_connection
    sock.connect(sa)
ConnectionRefusedError: [Errno 111] Connection refused

During handling of the above exception, another exception occurred:

Traceback (most recent call last):
  File "./index.py", line 20, in application
    init.mysql.connected(init.config['MYSQL']['host'],init.config['MYSQL']['port'],init.config['MYSQL']['database'],init.config['MYSQL']['user'],init.config['MYSQL']['password'])
  File "../lib/MySQLProvider.py", line 10, in connected
    self.connect = pymysql.connect(host=host,user=user,password=password,db=database,port=int(port))
  File "/usr/local/lib/python3.6/dist-packages/pymysql/__init__.py", line 94, in Connect
    return Connection(*args, **kwargs)
  File "/usr/local/lib/python3.6/dist-packages/pymysql/connections.py", line 325, in __init__
    self.connect()
  File "/usr/local/lib/python3.6/dist-packages/pymysql/connections.py", line 630, in connect
    raise exc
pymysql.err.OperationalError: (2003, "Can't connect to MySQL server on 'db' ([Errno 111] Connection refused)")
[pid: 1|app: 0|req: 2/2] 192.168.10.50 () {46 vars in 894 bytes} [Wed Apr  8 02:18:56 2020] GET /favicon.ico => generated 0 bytes in 4 msecs (HTTP/1.1 500) 0 headers in 0 bytes (0 switches on core 0)
[pid: 1|app: 0|req: 3/3] 192.168.10.50 () {44 vars in 928 bytes} [Wed Apr  8 02:19:17 2020] GET / => generated 3407 bytes in 101 msecs (HTTP/1.1 200) 1 headers in 44 bytes (1 switches on core 0)
[pid: 1|app: 0|req: 4/4] 192.168.10.50 () {46 vars in 894 bytes} [Wed Apr  8 02:19:18 2020] GET /favicon.ico => generated 2154 bytes in 7 msecs (HTTP/1.1 200) 1 headers in 44 bytes (1 switches on core 0)
[pid: 1|app: 0|req: 5/5] 192.168.10.50 () {44 vars in 928 bytes} [Wed Apr  8 02:19:31 2020] GET / => generated 3966 bytes in 12 msecs (HTTP/1.1 200) 1 headers in 44 bytes (1 switches on core 0)
[pid: 1|app: 0|req: 6/6] 192.168.10.50 () {46 vars in 894 bytes} [Wed Apr  8 02:19:31 2020] GET /favicon.ico => generated 2154 bytes in 6 msecs (HTTP/1.1 200) 1 headers in 44 bytes (1 switches on core 0)
[pid: 1|app: 0|req: 7/7] 192.168.10.50 () {44 vars in 869 bytes} [Wed Apr  8 02:19:36 2020] GET /cpe_inform_ajax?cpe_id=1 => generated 2497 bytes in 4 msecs (HTTP/1.1 200) 1 headers in 44 bytes (1 switches on core 0)
[pid: 1|app: 0|req: 8/8] 192.168.10.50 () {44 vars in 869 bytes} [Wed Apr  8 02:19:49 2020] GET /cpe_inform_ajax?cpe_id=1 => generated 2497 bytes in 4 msecs (HTTP/1.1 200) 1 headers in 44 bytes (1 switches on core 0)
*** Starting uWSGI 2.0.18 (64bit) on [Wed Apr  8 02:20:26 2020] ***
compiled with version: 7.5.0 on 07 April 2020 23:31:59
os: Linux-5.0.0-38-generic #41-Ubuntu SMP Tue Dec 3 00:27:35 UTC 2019
nodename: 89583f7261b8
machine: x86_64
clock source: unix
detected number of CPU cores: 12
current working directory: /nb/webroot
detected binary path: /usr/local/bin/uwsgi
!!! no internal routing support, rebuild with pcre support !!!
uWSGI running as root, you can use --uid/--gid/--chroot options
*** WARNING: you are running uWSGI as root !!! (use the --uid flag) *** 
*** WARNING: you are running uWSGI without its master process manager ***
your memory page size is 4096 bytes
detected max file descriptor number: 1048576
lock engine: pthread robust mutexes
thunder lock: disabled (you can enable it with --thunder-lock)
uwsgi socket 0 bound to TCP address 0.0.0.0:9201 fd 3
uWSGI running as root, you can use --uid/--gid/--chroot options
*** WARNING: you are running uWSGI as root !!! (use the --uid flag) *** 
Python version: 3.6.9 (default, Nov  7 2019, 10:44:02)  [GCC 8.3.0]
*** Python threads support is disabled. You can enable it with --enable-threads ***
Python main interpreter initialized at 0x5591e2526240
uWSGI running as root, you can use --uid/--gid/--chroot options
*** WARNING: you are running uWSGI as root !!! (use the --uid flag) *** 
your server socket listen backlog is limited to 100 connections
your mercy for graceful operations on workers is 60 seconds
mapped 72904 bytes (71 KB) for 1 cores
*** Operational MODE: single process ***
WSGI app 0 (mountpoint='') ready in 0 seconds on interpreter 0x5591e2526240 pid: 1 (default app)
uWSGI running as root, you can use --uid/--gid/--chroot options
*** WARNING: you are running uWSGI as root !!! (use the --uid flag) *** 
*** uWSGI is running in multiple interpreter mode ***
spawned uWSGI worker 1 (and the only) (pid: 1, cores: 1)
[pid: 1|app: 0|req: 1/1] 192.168.10.50 () {44 vars in 928 bytes} [Wed Apr  8 02:20:42 2020] GET / => generated 3966 bytes in 103 msecs (HTTP/1.1 200) 1 headers in 44 bytes (1 switches on core 0)
[pid: 1|app: 0|req: 2/2] 192.168.10.50 () {46 vars in 894 bytes} [Wed Apr  8 02:20:42 2020] GET /favicon.ico => generated 2154 bytes in 7 msecs (HTTP/1.1 200) 1 headers in 44 bytes (1 switches on core 0)
[pid: 1|app: 0|req: 3/3] 192.168.10.50 () {44 vars in 928 bytes} [Wed Apr  8 02:20:43 2020] GET / => generated 3966 bytes in 13 msecs (HTTP/1.1 200) 1 headers in 44 bytes (1 switches on core 0)
[pid: 1|app: 0|req: 4/4] 192.168.10.50 () {46 vars in 894 bytes} [Wed Apr  8 02:20:43 2020] GET /favicon.ico => generated 2154 bytes in 6 msecs (HTTP/1.1 200) 1 headers in 44 bytes (1 switches on core 0)
[pid: 1|app: 0|req: 5/5] 192.168.10.50 () {44 vars in 928 bytes} [Wed Apr  8 02:20:43 2020] GET / => generated 3966 bytes in 12 msecs (HTTP/1.1 200) 1 headers in 44 bytes (1 switches on core 0)
[pid: 1|app: 0|req: 6/6] 192.168.10.50 () {46 vars in 894 bytes} [Wed Apr  8 02:20:43 2020] GET /favicon.ico => generated 2154 bytes in 6 msecs (HTTP/1.1 200) 1 headers in 44 bytes (1 switches on core 0)
[pid: 1|app: 0|req: 7/7] 192.168.10.50 () {44 vars in 928 bytes} [Wed Apr  8 02:20:43 2020] GET / => generated 3966 bytes in 12 msecs (HTTP/1.1 200) 1 headers in 44 bytes (1 switches on core 0)
[pid: 1|app: 0|req: 8/8] 192.168.10.50 () {46 vars in 894 bytes} [Wed Apr  8 02:20:43 2020] GET /favicon.ico => generated 2154 bytes in 6 msecs (HTTP/1.1 200) 1 headers in 44 bytes (1 switches on core 0)
[pid: 1|app: 0|req: 9/9] 192.168.10.50 () {44 vars in 939 bytes} [Wed Apr  8 02:20:46 2020] GET / => generated 3966 bytes in 14 msecs (HTTP/1.1 200) 1 headers in 44 bytes (1 switches on core 0)
[pid: 1|app: 0|req: 10/10] 192.168.10.50 () {42 vars in 841 bytes} [Wed Apr  8 02:20:46 2020] GET /favicon.ico => generated 2154 bytes in 6 msecs (HTTP/1.1 200) 1 headers in 44 bytes (1 switches on core 0)
[pid: 1|app: 0|req: 11/11] 192.168.10.50 () {44 vars in 939 bytes} [Wed Apr  8 02:20:46 2020] GET / => generated 3966 bytes in 11 msecs (HTTP/1.1 200) 1 headers in 44 bytes (1 switches on core 0)
[pid: 1|app: 0|req: 12/12] 192.168.10.50 () {42 vars in 841 bytes} [Wed Apr  8 02:20:46 2020] GET /favicon.ico => generated 2154 bytes in 6 msecs (HTTP/1.1 200) 1 headers in 44 bytes (1 switches on core 0)
[pid: 1|app: 0|req: 13/13] 192.168.10.50 () {44 vars in 939 bytes} [Wed Apr  8 02:20:47 2020] GET / => generated 3966 bytes in 13 msecs (HTTP/1.1 200) 1 headers in 44 bytes (1 switches on core 0)
[pid: 1|app: 0|req: 14/14] 192.168.10.50 () {42 vars in 841 bytes} [Wed Apr  8 02:20:47 2020] GET /favicon.ico => generated 2154 bytes in 6 msecs (HTTP/1.1 200) 1 headers in 44 bytes (1 switches on core 0)
[pid: 1|app: 0|req: 15/15] 192.168.10.50 () {44 vars in 939 bytes} [Wed Apr  8 02:20:47 2020] GET / => generated 3966 bytes in 12 msecs (HTTP/1.1 200) 1 headers in 44 bytes (1 switches on core 0)
[pid: 1|app: 0|req: 16/16] 192.168.10.50 () {42 vars in 841 bytes} [Wed Apr  8 02:20:47 2020] GET /favicon.ico => generated 2154 bytes in 6 msecs (HTTP/1.1 200) 1 headers in 44 bytes (1 switches on core 0)
[pid: 1|app: 0|req: 17/17] 192.168.10.50 () {44 vars in 939 bytes} [Wed Apr  8 02:20:47 2020] GET / => generated 3966 bytes in 11 msecs (HTTP/1.1 200) 1 headers in 44 bytes (1 switches on core 0)
[pid: 1|app: 0|req: 18/18] 192.168.10.50 () {42 vars in 841 bytes} [Wed Apr  8 02:20:47 2020] GET /favicon.ico => generated 2154 bytes in 6 msecs (HTTP/1.1 200) 1 headers in 44 bytes (1 switches on core 0)
[pid: 1|app: 0|req: 19/19] 192.168.10.50 () {44 vars in 939 bytes} [Wed Apr  8 02:20:47 2020] GET / => generated 3966 bytes in 13 msecs (HTTP/1.1 200) 1 headers in 44 bytes (1 switches on core 0)
[pid: 1|app: 0|req: 20/20] 192.168.10.50 () {42 vars in 841 bytes} [Wed Apr  8 02:20:47 2020] GET /favicon.ico => generated 2154 bytes in 6 msecs (HTTP/1.1 200) 1 headers in 44 bytes (1 switches on core 0)
[pid: 1|app: 0|req: 21/21] 192.168.10.50 () {44 vars in 939 bytes} [Wed Apr  8 02:20:47 2020] GET / => generated 3966 bytes in 13 msecs (HTTP/1.1 200) 1 headers in 44 bytes (1 switches on core 0)
[pid: 1|app: 0|req: 22/22] 192.168.10.50 () {42 vars in 841 bytes} [Wed Apr  8 02:20:47 2020] GET /favicon.ico => generated 2154 bytes in 6 msecs (HTTP/1.1 200) 1 headers in 44 bytes (1 switches on core 0)
[pid: 1|app: 0|req: 23/23] 192.168.10.50 () {44 vars in 939 bytes} [Wed Apr  8 02:20:47 2020] GET / => generated 3966 bytes in 13 msecs (HTTP/1.1 200) 1 headers in 44 bytes (1 switches on core 0)
[pid: 1|app: 0|req: 24/24] 192.168.10.50 () {42 vars in 841 bytes} [Wed Apr  8 02:20:48 2020] GET /favicon.ico => generated 2154 bytes in 6 msecs (HTTP/1.1 200) 1 headers in 44 bytes (1 switches on core 0)
[pid: 1|app: 0|req: 25/25] 192.168.10.50 () {44 vars in 939 bytes} [Wed Apr  8 02:20:48 2020] GET / => generated 3966 bytes in 14 msecs (HTTP/1.1 200) 1 headers in 44 bytes (1 switches on core 0)
[pid: 1|app: 0|req: 26/26] 192.168.10.50 () {42 vars in 841 bytes} [Wed Apr  8 02:20:48 2020] GET /favicon.ico => generated 2154 bytes in 6 msecs (HTTP/1.1 200) 1 headers in 44 bytes (1 switches on core 0)
[pid: 1|app: 0|req: 27/27] 192.168.10.50 () {44 vars in 939 bytes} [Wed Apr  8 02:20:48 2020] GET / => generated 3966 bytes in 14 msecs (HTTP/1.1 200) 1 headers in 44 bytes (1 switches on core 0)
[pid: 1|app: 0|req: 28/28] 192.168.10.50 () {42 vars in 841 bytes} [Wed Apr  8 02:20:48 2020] GET /favicon.ico => generated 2154 bytes in 6 msecs (HTTP/1.1 200) 1 headers in 44 bytes (1 switches on core 0)
*** Starting uWSGI 2.0.18 (64bit) on [Wed Apr  8 02:21:06 2020] ***
compiled with version: 7.5.0 on 07 April 2020 23:31:59
os: Linux-5.0.0-38-generic #41-Ubuntu SMP Tue Dec 3 00:27:35 UTC 2019
nodename: 2c347b95255c
machine: x86_64
clock source: unix
detected number of CPU cores: 12
current working directory: /nb/webroot
detected binary path: /usr/local/bin/uwsgi
!!! no internal routing support, rebuild with pcre support !!!
uWSGI running as root, you can use --uid/--gid/--chroot options
*** WARNING: you are running uWSGI as root !!! (use the --uid flag) *** 
*** WARNING: you are running uWSGI without its master process manager ***
your memory page size is 4096 bytes
detected max file descriptor number: 1048576
lock engine: pthread robust mutexes
thunder lock: disabled (you can enable it with --thunder-lock)
uwsgi socket 0 bound to TCP address 0.0.0.0:9201 fd 3
uWSGI running as root, you can use --uid/--gid/--chroot options
*** WARNING: you are running uWSGI as root !!! (use the --uid flag) *** 
Python version: 3.6.9 (default, Nov  7 2019, 10:44:02)  [GCC 8.3.0]
*** Python threads support is disabled. You can enable it with --enable-threads ***
Python main interpreter initialized at 0x5621521ba240
uWSGI running as root, you can use --uid/--gid/--chroot options
*** WARNING: you are running uWSGI as root !!! (use the --uid flag) *** 
your server socket listen backlog is limited to 100 connections
your mercy for graceful operations on workers is 60 seconds
mapped 72904 bytes (71 KB) for 1 cores
*** Operational MODE: single process ***
WSGI app 0 (mountpoint='') ready in 0 seconds on interpreter 0x5621521ba240 pid: 1 (default app)
uWSGI running as root, you can use --uid/--gid/--chroot options
*** WARNING: you are running uWSGI as root !!! (use the --uid flag) *** 
*** uWSGI is running in multiple interpreter mode ***
spawned uWSGI worker 1 (and the only) (pid: 1, cores: 1)
Traceback (most recent call last):
  File "/usr/local/lib/python3.6/dist-packages/pymysql/connections.py", line 583, in connect
    **kwargs)
  File "/usr/lib/python3.6/socket.py", line 724, in create_connection
    raise err
  File "/usr/lib/python3.6/socket.py", line 713, in create_connection
    sock.connect(sa)
ConnectionRefusedError: [Errno 111] Connection refused

During handling of the above exception, another exception occurred:

Traceback (most recent call last):
  File "./index.py", line 20, in application
    init.mysql.connected(init.config['MYSQL']['host'],init.config['MYSQL']['port'],init.config['MYSQL']['database'],init.config['MYSQL']['user'],init.config['MYSQL']['password'])
  File "../lib/MySQLProvider.py", line 10, in connected
    self.connect = pymysql.connect(host=host,user=user,password=password,db=database,port=int(port))
  File "/usr/local/lib/python3.6/dist-packages/pymysql/__init__.py", line 94, in Connect
    return Connection(*args, **kwargs)
  File "/usr/local/lib/python3.6/dist-packages/pymysql/connections.py", line 325, in __init__
    self.connect()
  File "/usr/local/lib/python3.6/dist-packages/pymysql/connections.py", line 630, in connect
    raise exc
pymysql.err.OperationalError: (2003, "Can't connect to MySQL server on 'db' ([Errno 111] Connection refused)")
[pid: 1|app: 0|req: 1/1] 192.168.10.50 () {46 vars in 970 bytes} [Wed Apr  8 02:21:10 2020] GET / => generated 0 bytes in 9 msecs (HTTP/1.1 500) 0 headers in 0 bytes (0 switches on core 0)
Traceback (most recent call last):
  File "/usr/local/lib/python3.6/dist-packages/pymysql/connections.py", line 583, in connect
    **kwargs)
  File "/usr/lib/python3.6/socket.py", line 724, in create_connection
    raise err
  File "/usr/lib/python3.6/socket.py", line 713, in create_connection
    sock.connect(sa)
ConnectionRefusedError: [Errno 111] Connection refused

During handling of the above exception, another exception occurred:

Traceback (most recent call last):
  File "./index.py", line 20, in application
    init.mysql.connected(init.config['MYSQL']['host'],init.config['MYSQL']['port'],init.config['MYSQL']['database'],init.config['MYSQL']['user'],init.config['MYSQL']['password'])
  File "../lib/MySQLProvider.py", line 10, in connected
    self.connect = pymysql.connect(host=host,user=user,password=password,db=database,port=int(port))
  File "/usr/local/lib/python3.6/dist-packages/pymysql/__init__.py", line 94, in Connect
    return Connection(*args, **kwargs)
  File "/usr/local/lib/python3.6/dist-packages/pymysql/connections.py", line 325, in __init__
    self.connect()
  File "/usr/local/lib/python3.6/dist-packages/pymysql/connections.py", line 630, in connect
    raise exc
pymysql.err.OperationalError: (2003, "Can't connect to MySQL server on 'db' ([Errno 111] Connection refused)")
[pid: 1|app: 0|req: 2/2] 192.168.10.50 () {46 vars in 894 bytes} [Wed Apr  8 02:21:10 2020] GET /favicon.ico => generated 0 bytes in 4 msecs (HTTP/1.1 500) 0 headers in 0 bytes (0 switches on core 0)
Traceback (most recent call last):
  File "/usr/local/lib/python3.6/dist-packages/pymysql/connections.py", line 583, in connect
    **kwargs)
  File "/usr/lib/python3.6/socket.py", line 724, in create_connection
    raise err
  File "/usr/lib/python3.6/socket.py", line 713, in create_connection
    sock.connect(sa)
ConnectionRefusedError: [Errno 111] Connection refused

During handling of the above exception, another exception occurred:

Traceback (most recent call last):
  File "./index.py", line 20, in application
    init.mysql.connected(init.config['MYSQL']['host'],init.config['MYSQL']['port'],init.config['MYSQL']['database'],init.config['MYSQL']['user'],init.config['MYSQL']['password'])
  File "../lib/MySQLProvider.py", line 10, in connected
    self.connect = pymysql.connect(host=host,user=user,password=password,db=database,port=int(port))
  File "/usr/local/lib/python3.6/dist-packages/pymysql/__init__.py", line 94, in Connect
    return Connection(*args, **kwargs)
  File "/usr/local/lib/python3.6/dist-packages/pymysql/connections.py", line 325, in __init__
    self.connect()
  File "/usr/local/lib/python3.6/dist-packages/pymysql/connections.py", line 630, in connect
    raise exc
pymysql.err.OperationalError: (2003, "Can't connect to MySQL server on 'db' ([Errno 111] Connection refused)")
[pid: 1|app: 0|req: 3/3] 192.168.10.50 () {46 vars in 970 bytes} [Wed Apr  8 02:21:11 2020] GET / => generated 0 bytes in 4 msecs (HTTP/1.1 500) 0 headers in 0 bytes (0 switches on core 0)
Traceback (most recent call last):
  File "/usr/local/lib/python3.6/dist-packages/pymysql/connections.py", line 583, in connect
    **kwargs)
  File "/usr/lib/python3.6/socket.py", line 724, in create_connection
    raise err
  File "/usr/lib/python3.6/socket.py", line 713, in create_connection
    sock.connect(sa)
ConnectionRefusedError: [Errno 111] Connection refused

During handling of the above exception, another exception occurred:

Traceback (most recent call last):
  File "./index.py", line 20, in application
    init.mysql.connected(init.config['MYSQL']['host'],init.config['MYSQL']['port'],init.config['MYSQL']['database'],init.config['MYSQL']['user'],init.config['MYSQL']['password'])
  File "../lib/MySQLProvider.py", line 10, in connected
    self.connect = pymysql.connect(host=host,user=user,password=password,db=database,port=int(port))
  File "/usr/local/lib/python3.6/dist-packages/pymysql/__init__.py", line 94, in Connect
    return Connection(*args, **kwargs)
  File "/usr/local/lib/python3.6/dist-packages/pymysql/connections.py", line 325, in __init__
    self.connect()
  File "/usr/local/lib/python3.6/dist-packages/pymysql/connections.py", line 630, in connect
    raise exc
pymysql.err.OperationalError: (2003, "Can't connect to MySQL server on 'db' ([Errno 111] Connection refused)")
[pid: 1|app: 0|req: 4/4] 192.168.10.50 () {46 vars in 894 bytes} [Wed Apr  8 02:21:11 2020] GET /favicon.ico => generated 0 bytes in 5 msecs (HTTP/1.1 500) 0 headers in 0 bytes (0 switches on core 0)
Traceback (most recent call last):
  File "/usr/local/lib/python3.6/dist-packages/pymysql/connections.py", line 583, in connect
    **kwargs)
  File "/usr/lib/python3.6/socket.py", line 724, in create_connection
    raise err
  File "/usr/lib/python3.6/socket.py", line 713, in create_connection
    sock.connect(sa)
ConnectionRefusedError: [Errno 111] Connection refused

During handling of the above exception, another exception occurred:

Traceback (most recent call last):
  File "./index.py", line 20, in application
    init.mysql.connected(init.config['MYSQL']['host'],init.config['MYSQL']['port'],init.config['MYSQL']['database'],init.config['MYSQL']['user'],init.config['MYSQL']['password'])
  File "../lib/MySQLProvider.py", line 10, in connected
    self.connect = pymysql.connect(host=host,user=user,password=password,db=database,port=int(port))
  File "/usr/local/lib/python3.6/dist-packages/pymysql/__init__.py", line 94, in Connect
    return Connection(*args, **kwargs)
  File "/usr/local/lib/python3.6/dist-packages/pymysql/connections.py", line 325, in __init__
    self.connect()
  File "/usr/local/lib/python3.6/dist-packages/pymysql/connections.py", line 630, in connect
    raise exc
pymysql.err.OperationalError: (2003, "Can't connect to MySQL server on 'db' ([Errno 111] Connection refused)")
[pid: 1|app: 0|req: 5/5] 192.168.10.50 () {46 vars in 970 bytes} [Wed Apr  8 02:21:11 2020] GET / => generated 0 bytes in 4 msecs (HTTP/1.1 500) 0 headers in 0 bytes (0 switches on core 0)
Traceback (most recent call last):
  File "/usr/local/lib/python3.6/dist-packages/pymysql/connections.py", line 583, in connect
    **kwargs)
  File "/usr/lib/python3.6/socket.py", line 724, in create_connection
    raise err
  File "/usr/lib/python3.6/socket.py", line 713, in create_connection
    sock.connect(sa)
ConnectionRefusedError: [Errno 111] Connection refused

During handling of the above exception, another exception occurred:

Traceback (most recent call last):
  File "./index.py", line 20, in application
    init.mysql.connected(init.config['MYSQL']['host'],init.config['MYSQL']['port'],init.config['MYSQL']['database'],init.config['MYSQL']['user'],init.config['MYSQL']['password'])
  File "../lib/MySQLProvider.py", line 10, in connected
    self.connect = pymysql.connect(host=host,user=user,password=password,db=database,port=int(port))
  File "/usr/local/lib/python3.6/dist-packages/pymysql/__init__.py", line 94, in Connect
    return Connection(*args, **kwargs)
  File "/usr/local/lib/python3.6/dist-packages/pymysql/connections.py", line 325, in __init__
    self.connect()
  File "/usr/local/lib/python3.6/dist-packages/pymysql/connections.py", line 630, in connect
    raise exc
pymysql.err.OperationalError: (2003, "Can't connect to MySQL server on 'db' ([Errno 111] Connection refused)")
[pid: 1|app: 0|req: 6/6] 192.168.10.50 () {46 vars in 894 bytes} [Wed Apr  8 02:21:11 2020] GET /favicon.ico => generated 0 bytes in 4 msecs (HTTP/1.1 500) 0 headers in 0 bytes (0 switches on core 0)
Traceback (most recent call last):
  File "/usr/local/lib/python3.6/dist-packages/pymysql/connections.py", line 583, in connect
    **kwargs)
  File "/usr/lib/python3.6/socket.py", line 724, in create_connection
    raise err
  File "/usr/lib/python3.6/socket.py", line 713, in create_connection
    sock.connect(sa)
ConnectionRefusedError: [Errno 111] Connection refused

During handling of the above exception, another exception occurred:

Traceback (most recent call last):
  File "./index.py", line 20, in application
    init.mysql.connected(init.config['MYSQL']['host'],init.config['MYSQL']['port'],init.config['MYSQL']['database'],init.config['MYSQL']['user'],init.config['MYSQL']['password'])
  File "../lib/MySQLProvider.py", line 10, in connected
    self.connect = pymysql.connect(host=host,user=user,password=password,db=database,port=int(port))
  File "/usr/local/lib/python3.6/dist-packages/pymysql/__init__.py", line 94, in Connect
    return Connection(*args, **kwargs)
  File "/usr/local/lib/python3.6/dist-packages/pymysql/connections.py", line 325, in __init__
    self.connect()
  File "/usr/local/lib/python3.6/dist-packages/pymysql/connections.py", line 630, in connect
    raise exc
pymysql.err.OperationalError: (2003, "Can't connect to MySQL server on 'db' ([Errno 111] Connection refused)")
[pid: 1|app: 0|req: 7/7] 192.168.10.50 () {46 vars in 970 bytes} [Wed Apr  8 02:21:11 2020] GET / => generated 0 bytes in 4 msecs (HTTP/1.1 500) 0 headers in 0 bytes (0 switches on core 0)
Traceback (most recent call last):
  File "/usr/local/lib/python3.6/dist-packages/pymysql/connections.py", line 583, in connect
    **kwargs)
  File "/usr/lib/python3.6/socket.py", line 724, in create_connection
    raise err
  File "/usr/lib/python3.6/socket.py", line 713, in create_connection
    sock.connect(sa)
ConnectionRefusedError: [Errno 111] Connection refused

During handling of the above exception, another exception occurred:

Traceback (most recent call last):
  File "./index.py", line 20, in application
    init.mysql.connected(init.config['MYSQL']['host'],init.config['MYSQL']['port'],init.config['MYSQL']['database'],init.config['MYSQL']['user'],init.config['MYSQL']['password'])
  File "../lib/MySQLProvider.py", line 10, in connected
    self.connect = pymysql.connect(host=host,user=user,password=password,db=database,port=int(port))
  File "/usr/local/lib/python3.6/dist-packages/pymysql/__init__.py", line 94, in Connect
    return Connection(*args, **kwargs)
  File "/usr/local/lib/python3.6/dist-packages/pymysql/connections.py", line 325, in __init__
    self.connect()
  File "/usr/local/lib/python3.6/dist-packages/pymysql/connections.py", line 630, in connect
    raise exc
pymysql.err.OperationalError: (2003, "Can't connect to MySQL server on 'db' ([Errno 111] Connection refused)")
[pid: 1|app: 0|req: 8/8] 192.168.10.50 () {46 vars in 894 bytes} [Wed Apr  8 02:21:11 2020] GET /favicon.ico => generated 0 bytes in 4 msecs (HTTP/1.1 500) 0 headers in 0 bytes (0 switches on core 0)
Traceback (most recent call last):
  File "/usr/local/lib/python3.6/dist-packages/pymysql/connections.py", line 583, in connect
    **kwargs)
  File "/usr/lib/python3.6/socket.py", line 724, in create_connection
    raise err
  File "/usr/lib/python3.6/socket.py", line 713, in create_connection
    sock.connect(sa)
ConnectionRefusedError: [Errno 111] Connection refused

During handling of the above exception, another exception occurred:

Traceback (most recent call last):
  File "./index.py", line 20, in application
    init.mysql.connected(init.config['MYSQL']['host'],init.config['MYSQL']['port'],init.config['MYSQL']['database'],init.config['MYSQL']['user'],init.config['MYSQL']['password'])
  File "../lib/MySQLProvider.py", line 10, in connected
    self.connect = pymysql.connect(host=host,user=user,password=password,db=database,port=int(port))
  File "/usr/local/lib/python3.6/dist-packages/pymysql/__init__.py", line 94, in Connect
    return Connection(*args, **kwargs)
  File "/usr/local/lib/python3.6/dist-packages/pymysql/connections.py", line 325, in __init__
    self.connect()
  File "/usr/local/lib/python3.6/dist-packages/pymysql/connections.py", line 630, in connect
    raise exc
pymysql.err.OperationalError: (2003, "Can't connect to MySQL server on 'db' ([Errno 111] Connection refused)")
[pid: 1|app: 0|req: 9/9] 192.168.10.50 () {46 vars in 970 bytes} [Wed Apr  8 02:21:23 2020] GET / => generated 0 bytes in 5 msecs (HTTP/1.1 500) 0 headers in 0 bytes (0 switches on core 0)
Traceback (most recent call last):
  File "/usr/local/lib/python3.6/dist-packages/pymysql/connections.py", line 583, in connect
    **kwargs)
  File "/usr/lib/python3.6/socket.py", line 724, in create_connection
    raise err
  File "/usr/lib/python3.6/socket.py", line 713, in create_connection
    sock.connect(sa)
ConnectionRefusedError: [Errno 111] Connection refused

During handling of the above exception, another exception occurred:

Traceback (most recent call last):
  File "./index.py", line 20, in application
    init.mysql.connected(init.config['MYSQL']['host'],init.config['MYSQL']['port'],init.config['MYSQL']['database'],init.config['MYSQL']['user'],init.config['MYSQL']['password'])
  File "../lib/MySQLProvider.py", line 10, in connected
    self.connect = pymysql.connect(host=host,user=user,password=password,db=database,port=int(port))
  File "/usr/local/lib/python3.6/dist-packages/pymysql/__init__.py", line 94, in Connect
    return Connection(*args, **kwargs)
  File "/usr/local/lib/python3.6/dist-packages/pymysql/connections.py", line 325, in __init__
    self.connect()
  File "/usr/local/lib/python3.6/dist-packages/pymysql/connections.py", line 630, in connect
    raise exc
pymysql.err.OperationalError: (2003, "Can't connect to MySQL server on 'db' ([Errno 111] Connection refused)")
[pid: 1|app: 0|req: 10/10] 192.168.10.50 () {46 vars in 894 bytes} [Wed Apr  8 02:21:23 2020] GET /favicon.ico => generated 0 bytes in 4 msecs (HTTP/1.1 500) 0 headers in 0 bytes (0 switches on core 0)
Traceback (most recent call last):
  File "/usr/local/lib/python3.6/dist-packages/pymysql/connections.py", line 583, in connect
    **kwargs)
  File "/usr/lib/python3.6/socket.py", line 724, in create_connection
    raise err
  File "/usr/lib/python3.6/socket.py", line 713, in create_connection
    sock.connect(sa)
ConnectionRefusedError: [Errno 111] Connection refused

During handling of the above exception, another exception occurred:

Traceback (most recent call last):
  File "./index.py", line 20, in application
    init.mysql.connected(init.config['MYSQL']['host'],init.config['MYSQL']['port'],init.config['MYSQL']['database'],init.config['MYSQL']['user'],init.config['MYSQL']['password'])
  File "../lib/MySQLProvider.py", line 10, in connected
    self.connect = pymysql.connect(host=host,user=user,password=password,db=database,port=int(port))
  File "/usr/local/lib/python3.6/dist-packages/pymysql/__init__.py", line 94, in Connect
    return Connection(*args, **kwargs)
  File "/usr/local/lib/python3.6/dist-packages/pymysql/connections.py", line 325, in __init__
    self.connect()
  File "/usr/local/lib/python3.6/dist-packages/pymysql/connections.py", line 630, in connect
    raise exc
pymysql.err.OperationalError: (2003, "Can't connect to MySQL server on 'db' ([Errno 111] Connection refused)")
[pid: 1|app: 0|req: 11/11] 192.168.10.50 () {46 vars in 970 bytes} [Wed Apr  8 02:21:24 2020] GET / => generated 0 bytes in 4 msecs (HTTP/1.1 500) 0 headers in 0 bytes (0 switches on core 0)
Traceback (most recent call last):
  File "/usr/local/lib/python3.6/dist-packages/pymysql/connections.py", line 583, in connect
    **kwargs)
  File "/usr/lib/python3.6/socket.py", line 724, in create_connection
    raise err
  File "/usr/lib/python3.6/socket.py", line 713, in create_connection
    sock.connect(sa)
ConnectionRefusedError: [Errno 111] Connection refused

During handling of the above exception, another exception occurred:

Traceback (most recent call last):
  File "./index.py", line 20, in application
    init.mysql.connected(init.config['MYSQL']['host'],init.config['MYSQL']['port'],init.config['MYSQL']['database'],init.config['MYSQL']['user'],init.config['MYSQL']['password'])
  File "../lib/MySQLProvider.py", line 10, in connected
    self.connect = pymysql.connect(host=host,user=user,password=password,db=database,port=int(port))
  File "/usr/local/lib/python3.6/dist-packages/pymysql/__init__.py", line 94, in Connect
    return Connection(*args, **kwargs)
  File "/usr/local/lib/python3.6/dist-packages/pymysql/connections.py", line 325, in __init__
    self.connect()
  File "/usr/local/lib/python3.6/dist-packages/pymysql/connections.py", line 630, in connect
    raise exc
pymysql.err.OperationalError: (2003, "Can't connect to MySQL server on 'db' ([Errno 111] Connection refused)")
[pid: 1|app: 0|req: 12/12] 192.168.10.50 () {46 vars in 894 bytes} [Wed Apr  8 02:21:24 2020] GET /favicon.ico => generated 0 bytes in 3 msecs (HTTP/1.1 500) 0 headers in 0 bytes (0 switches on core 0)
[pid: 1|app: 0|req: 13/13] 192.168.10.50 () {46 vars in 970 bytes} [Wed Apr  8 02:21:42 2020] GET / => generated 3966 bytes in 17 msecs (HTTP/1.1 200) 1 headers in 44 bytes (1 switches on core 0)
[pid: 1|app: 0|req: 14/14] 192.168.10.50 () {46 vars in 894 bytes} [Wed Apr  8 02:21:42 2020] GET /favicon.ico => generated 2154 bytes in 6 msecs (HTTP/1.1 200) 1 headers in 44 bytes (1 switches on core 0)
[pid: 1|app: 0|req: 15/15] 192.168.10.50 () {46 vars in 970 bytes} [Wed Apr  8 02:21:43 2020] GET / => generated 3966 bytes in 14 msecs (HTTP/1.1 200) 1 headers in 44 bytes (1 switches on core 0)
[pid: 1|app: 0|req: 16/16] 192.168.10.50 () {46 vars in 894 bytes} [Wed Apr  8 02:21:43 2020] GET /favicon.ico => generated 2154 bytes in 6 msecs (HTTP/1.1 200) 1 headers in 44 bytes (1 switches on core 0)
[pid: 1|app: 0|req: 17/17] 192.168.10.50 () {46 vars in 970 bytes} [Wed Apr  8 02:21:43 2020] GET / => generated 3966 bytes in 12 msecs (HTTP/1.1 200) 1 headers in 44 bytes (1 switches on core 0)
[pid: 1|app: 0|req: 18/18] 192.168.10.50 () {46 vars in 894 bytes} [Wed Apr  8 02:21:43 2020] GET /favicon.ico => generated 2154 bytes in 6 msecs (HTTP/1.1 200) 1 headers in 44 bytes (1 switches on core 0)
[pid: 1|app: 0|req: 19/19] 192.168.10.50 () {46 vars in 970 bytes} [Wed Apr  8 02:21:43 2020] GET / => generated 3966 bytes in 12 msecs (HTTP/1.1 200) 1 headers in 44 bytes (1 switches on core 0)
[pid: 1|app: 0|req: 20/20] 192.168.10.50 () {46 vars in 894 bytes} [Wed Apr  8 02:21:43 2020] GET /favicon.ico => generated 2154 bytes in 6 msecs (HTTP/1.1 200) 1 headers in 44 bytes (1 switches on core 0)
[pid: 1|app: 0|req: 21/21] 192.168.10.50 () {44 vars in 980 bytes} [Wed Apr  8 02:21:51 2020] GET /cpe_commands?cpe_id=1 => generated 6000 bytes in 24 msecs (HTTP/1.1 200) 1 headers in 44 bytes (1 switches on core 0)
[pid: 1|app: 0|req: 22/22] 192.168.10.50 () {42 vars in 862 bytes} [Wed Apr  8 02:21:51 2020] GET /favicon.ico => generated 2154 bytes in 6 msecs (HTTP/1.1 200) 1 headers in 44 bytes (1 switches on core 0)
[pid: 1|app: 0|req: 23/23] 192.168.10.50 () {52 vars in 1178 bytes} [Wed Apr  8 02:21:54 2020] POST /cpe_add_commands => generated 0 bytes in 7 msecs (HTTP/1.1 301) 1 headers in 68 bytes (1 switches on core 0)
[pid: 1|app: 0|req: 24/24] 192.168.10.50 () {46 vars in 1032 bytes} [Wed Apr  8 02:21:54 2020] GET /cpe_commands?cpe_id=1 => generated 6535 bytes in 19 msecs (HTTP/1.1 200) 1 headers in 44 bytes (1 switches on core 0)
[pid: 1|app: 0|req: 25/25] 192.168.10.50 () {42 vars in 862 bytes} [Wed Apr  8 02:21:54 2020] GET /favicon.ico => generated 2154 bytes in 6 msecs (HTTP/1.1 200) 1 headers in 44 bytes (1 switches on core 0)
[pid: 1|app: 0|req: 26/26] 192.168.10.50 () {44 vars in 1019 bytes} [Wed Apr  8 02:22:02 2020] GET /cpe_del_commands?cpe_id=1&id=1 => generated 0 bytes in 5 msecs (HTTP/1.1 301) 1 headers in 68 bytes (1 switches on core 0)
[pid: 1|app: 0|req: 27/27] 192.168.10.50 () {44 vars in 1001 bytes} [Wed Apr  8 02:22:02 2020] GET /cpe_commands?cpe_id=1 => generated 6000 bytes in 18 msecs (HTTP/1.1 200) 1 headers in 44 bytes (1 switches on core 0)
[pid: 1|app: 0|req: 28/28] 192.168.10.50 () {42 vars in 862 bytes} [Wed Apr  8 02:22:02 2020] GET /favicon.ico => generated 2154 bytes in 6 msecs (HTTP/1.1 200) 1 headers in 44 bytes (1 switches on core 0)
[pid: 1|app: 0|req: 29/29] 192.168.10.50 () {44 vars in 960 bytes} [Wed Apr  8 02:22:05 2020] GET / => generated 3966 bytes in 11 msecs (HTTP/1.1 200) 1 headers in 44 bytes (1 switches on core 0)
[pid: 1|app: 0|req: 30/30] 192.168.10.50 () {42 vars in 841 bytes} [Wed Apr  8 02:22:05 2020] GET /favicon.ico => generated 2154 bytes in 6 msecs (HTTP/1.1 200) 1 headers in 44 bytes (1 switches on core 0)
[pid: 1|app: 0|req: 31/31] 192.168.10.50 () {44 vars in 939 bytes} [Wed Apr  8 02:22:21 2020] GET / => generated 4523 bytes in 11 msecs (HTTP/1.1 200) 1 headers in 44 bytes (1 switches on core 0)
[pid: 1|app: 0|req: 32/32] 192.168.10.50 () {42 vars in 841 bytes} [Wed Apr  8 02:22:21 2020] GET /favicon.ico => generated 2154 bytes in 6 msecs (HTTP/1.1 200) 1 headers in 44 bytes (1 switches on core 0)
*** Starting uWSGI 2.0.18 (64bit) on [Wed Apr  8 02:23:39 2020] ***
compiled with version: 7.5.0 on 07 April 2020 23:31:59
os: Linux-5.0.0-38-generic #41-Ubuntu SMP Tue Dec 3 00:27:35 UTC 2019
nodename: 62451e7a9995
machine: x86_64
clock source: unix
detected number of CPU cores: 12
current working directory: /nb/webroot
detected binary path: /usr/local/bin/uwsgi
!!! no internal routing support, rebuild with pcre support !!!
uWSGI running as root, you can use --uid/--gid/--chroot options
*** WARNING: you are running uWSGI as root !!! (use the --uid flag) *** 
*** WARNING: you are running uWSGI without its master process manager ***
your memory page size is 4096 bytes
detected max file descriptor number: 1048576
lock engine: pthread robust mutexes
thunder lock: disabled (you can enable it with --thunder-lock)
uwsgi socket 0 bound to TCP address 0.0.0.0:9201 fd 3
uWSGI running as root, you can use --uid/--gid/--chroot options
*** WARNING: you are running uWSGI as root !!! (use the --uid flag) *** 
Python version: 3.6.9 (default, Nov  7 2019, 10:44:02)  [GCC 8.3.0]
*** Python threads support is disabled. You can enable it with --enable-threads ***
Python main interpreter initialized at 0x55c848d5d240
uWSGI running as root, you can use --uid/--gid/--chroot options
*** WARNING: you are running uWSGI as root !!! (use the --uid flag) *** 
your server socket listen backlog is limited to 100 connections
your mercy for graceful operations on workers is 60 seconds
mapped 72904 bytes (71 KB) for 1 cores
*** Operational MODE: single process ***
WSGI app 0 (mountpoint='') ready in 0 seconds on interpreter 0x55c848d5d240 pid: 1 (default app)
uWSGI running as root, you can use --uid/--gid/--chroot options
*** WARNING: you are running uWSGI as root !!! (use the --uid flag) *** 
*** uWSGI is running in multiple interpreter mode ***
spawned uWSGI worker 1 (and the only) (pid: 1, cores: 1)
Traceback (most recent call last):
  File "/usr/local/lib/python3.6/dist-packages/pymysql/connections.py", line 583, in connect
    **kwargs)
  File "/usr/lib/python3.6/socket.py", line 724, in create_connection
    raise err
  File "/usr/lib/python3.6/socket.py", line 713, in create_connection
    sock.connect(sa)
ConnectionRefusedError: [Errno 111] Connection refused

During handling of the above exception, another exception occurred:

Traceback (most recent call last):
  File "./index.py", line 20, in application
    init.mysql.connected(init.config['MYSQL']['host'],init.config['MYSQL']['port'],init.config['MYSQL']['database'],init.config['MYSQL']['user'],init.config['MYSQL']['password'])
  File "../lib/MySQLProvider.py", line 10, in connected
    self.connect = pymysql.connect(host=host,user=user,password=password,db=database,port=int(port))
  File "/usr/local/lib/python3.6/dist-packages/pymysql/__init__.py", line 94, in Connect
    return Connection(*args, **kwargs)
  File "/usr/local/lib/python3.6/dist-packages/pymysql/connections.py", line 325, in __init__
    self.connect()
  File "/usr/local/lib/python3.6/dist-packages/pymysql/connections.py", line 630, in connect
    raise exc
pymysql.err.OperationalError: (2003, "Can't connect to MySQL server on 'db' ([Errno 111] Connection refused)")
[pid: 1|app: 0|req: 1/1] 192.168.10.50 () {46 vars in 970 bytes} [Wed Apr  8 02:23:44 2020] GET / => generated 0 bytes in 7 msecs (HTTP/1.1 500) 0 headers in 0 bytes (0 switches on core 0)
Traceback (most recent call last):
  File "/usr/local/lib/python3.6/dist-packages/pymysql/connections.py", line 583, in connect
    **kwargs)
  File "/usr/lib/python3.6/socket.py", line 724, in create_connection
    raise err
  File "/usr/lib/python3.6/socket.py", line 713, in create_connection
    sock.connect(sa)
ConnectionRefusedError: [Errno 111] Connection refused

During handling of the above exception, another exception occurred:

Traceback (most recent call last):
  File "./index.py", line 20, in application
    init.mysql.connected(init.config['MYSQL']['host'],init.config['MYSQL']['port'],init.config['MYSQL']['database'],init.config['MYSQL']['user'],init.config['MYSQL']['password'])
  File "../lib/MySQLProvider.py", line 10, in connected
    self.connect = pymysql.connect(host=host,user=user,password=password,db=database,port=int(port))
  File "/usr/local/lib/python3.6/dist-packages/pymysql/__init__.py", line 94, in Connect
    return Connection(*args, **kwargs)
  File "/usr/local/lib/python3.6/dist-packages/pymysql/connections.py", line 325, in __init__
    self.connect()
  File "/usr/local/lib/python3.6/dist-packages/pymysql/connections.py", line 630, in connect
    raise exc
pymysql.err.OperationalError: (2003, "Can't connect to MySQL server on 'db' ([Errno 111] Connection refused)")
[pid: 1|app: 0|req: 2/2] 192.168.10.50 () {46 vars in 894 bytes} [Wed Apr  8 02:23:45 2020] GET /favicon.ico => generated 0 bytes in 5 msecs (HTTP/1.1 500) 0 headers in 0 bytes (0 switches on core 0)
Traceback (most recent call last):
  File "/usr/local/lib/python3.6/dist-packages/pymysql/connections.py", line 583, in connect
    **kwargs)
  File "/usr/lib/python3.6/socket.py", line 724, in create_connection
    raise err
  File "/usr/lib/python3.6/socket.py", line 713, in create_connection
    sock.connect(sa)
ConnectionRefusedError: [Errno 111] Connection refused

During handling of the above exception, another exception occurred:

Traceback (most recent call last):
  File "./index.py", line 20, in application
    init.mysql.connected(init.config['MYSQL']['host'],init.config['MYSQL']['port'],init.config['MYSQL']['database'],init.config['MYSQL']['user'],init.config['MYSQL']['password'])
  File "../lib/MySQLProvider.py", line 10, in connected
    self.connect = pymysql.connect(host=host,user=user,password=password,db=database,port=int(port))
  File "/usr/local/lib/python3.6/dist-packages/pymysql/__init__.py", line 94, in Connect
    return Connection(*args, **kwargs)
  File "/usr/local/lib/python3.6/dist-packages/pymysql/connections.py", line 325, in __init__
    self.connect()
  File "/usr/local/lib/python3.6/dist-packages/pymysql/connections.py", line 630, in connect
    raise exc
pymysql.err.OperationalError: (2003, "Can't connect to MySQL server on 'db' ([Errno 111] Connection refused)")
[pid: 1|app: 0|req: 3/3] 192.168.10.50 () {46 vars in 970 bytes} [Wed Apr  8 02:23:45 2020] GET / => generated 0 bytes in 4 msecs (HTTP/1.1 500) 0 headers in 0 bytes (0 switches on core 0)
Traceback (most recent call last):
  File "/usr/local/lib/python3.6/dist-packages/pymysql/connections.py", line 583, in connect
    **kwargs)
  File "/usr/lib/python3.6/socket.py", line 724, in create_connection
    raise err
  File "/usr/lib/python3.6/socket.py", line 713, in create_connection
    sock.connect(sa)
ConnectionRefusedError: [Errno 111] Connection refused

During handling of the above exception, another exception occurred:

Traceback (most recent call last):
  File "./index.py", line 20, in application
    init.mysql.connected(init.config['MYSQL']['host'],init.config['MYSQL']['port'],init.config['MYSQL']['database'],init.config['MYSQL']['user'],init.config['MYSQL']['password'])
  File "../lib/MySQLProvider.py", line 10, in connected
    self.connect = pymysql.connect(host=host,user=user,password=password,db=database,port=int(port))
  File "/usr/local/lib/python3.6/dist-packages/pymysql/__init__.py", line 94, in Connect
    return Connection(*args, **kwargs)
  File "/usr/local/lib/python3.6/dist-packages/pymysql/connections.py", line 325, in __init__
    self.connect()
  File "/usr/local/lib/python3.6/dist-packages/pymysql/connections.py", line 630, in connect
    raise exc
pymysql.err.OperationalError: (2003, "Can't connect to MySQL server on 'db' ([Errno 111] Connection refused)")
[pid: 1|app: 0|req: 4/4] 192.168.10.50 () {46 vars in 894 bytes} [Wed Apr  8 02:23:45 2020] GET /favicon.ico => generated 0 bytes in 4 msecs (HTTP/1.1 500) 0 headers in 0 bytes (0 switches on core 0)
Traceback (most recent call last):
  File "/usr/local/lib/python3.6/dist-packages/pymysql/connections.py", line 583, in connect
    **kwargs)
  File "/usr/lib/python3.6/socket.py", line 724, in create_connection
    raise err
  File "/usr/lib/python3.6/socket.py", line 713, in create_connection
    sock.connect(sa)
ConnectionRefusedError: [Errno 111] Connection refused

During handling of the above exception, another exception occurred:

Traceback (most recent call last):
  File "./index.py", line 20, in application
    init.mysql.connected(init.config['MYSQL']['host'],init.config['MYSQL']['port'],init.config['MYSQL']['database'],init.config['MYSQL']['user'],init.config['MYSQL']['password'])
  File "../lib/MySQLProvider.py", line 10, in connected
    self.connect = pymysql.connect(host=host,user=user,password=password,db=database,port=int(port))
  File "/usr/local/lib/python3.6/dist-packages/pymysql/__init__.py", line 94, in Connect
    return Connection(*args, **kwargs)
  File "/usr/local/lib/python3.6/dist-packages/pymysql/connections.py", line 325, in __init__
    self.connect()
  File "/usr/local/lib/python3.6/dist-packages/pymysql/connections.py", line 630, in connect
    raise exc
pymysql.err.OperationalError: (2003, "Can't connect to MySQL server on 'db' ([Errno 111] Connection refused)")
[pid: 1|app: 0|req: 5/5] 192.168.10.50 () {46 vars in 970 bytes} [Wed Apr  8 02:23:45 2020] GET / => generated 0 bytes in 4 msecs (HTTP/1.1 500) 0 headers in 0 bytes (0 switches on core 0)
Traceback (most recent call last):
  File "/usr/local/lib/python3.6/dist-packages/pymysql/connections.py", line 583, in connect
    **kwargs)
  File "/usr/lib/python3.6/socket.py", line 724, in create_connection
    raise err
  File "/usr/lib/python3.6/socket.py", line 713, in create_connection
    sock.connect(sa)
ConnectionRefusedError: [Errno 111] Connection refused

During handling of the above exception, another exception occurred:

Traceback (most recent call last):
  File "./index.py", line 20, in application
    init.mysql.connected(init.config['MYSQL']['host'],init.config['MYSQL']['port'],init.config['MYSQL']['database'],init.config['MYSQL']['user'],init.config['MYSQL']['password'])
  File "../lib/MySQLProvider.py", line 10, in connected
    self.connect = pymysql.connect(host=host,user=user,password=password,db=database,port=int(port))
  File "/usr/local/lib/python3.6/dist-packages/pymysql/__init__.py", line 94, in Connect
    return Connection(*args, **kwargs)
  File "/usr/local/lib/python3.6/dist-packages/pymysql/connections.py", line 325, in __init__
    self.connect()
  File "/usr/local/lib/python3.6/dist-packages/pymysql/connections.py", line 630, in connect
    raise exc
pymysql.err.OperationalError: (2003, "Can't connect to MySQL server on 'db' ([Errno 111] Connection refused)")
[pid: 1|app: 0|req: 6/6] 192.168.10.50 () {46 vars in 894 bytes} [Wed Apr  8 02:23:45 2020] GET /favicon.ico => generated 0 bytes in 4 msecs (HTTP/1.1 500) 0 headers in 0 bytes (0 switches on core 0)
[pid: 1|app: 0|req: 7/7] 192.168.10.50 () {46 vars in 970 bytes} [Wed Apr  8 02:23:59 2020] GET / => generated 3407 bytes in 94 msecs (HTTP/1.1 200) 1 headers in 44 bytes (1 switches on core 0)
[pid: 1|app: 0|req: 8/8] 192.168.10.50 () {46 vars in 894 bytes} [Wed Apr  8 02:24:00 2020] GET /favicon.ico => generated 2154 bytes in 7 msecs (HTTP/1.1 200) 1 headers in 44 bytes (1 switches on core 0)
[pid: 1|app: 0|req: 9/9] 192.168.10.50 () {46 vars in 970 bytes} [Wed Apr  8 02:24:00 2020] GET / => generated 3407 bytes in 12 msecs (HTTP/1.1 200) 1 headers in 44 bytes (1 switches on core 0)
[pid: 1|app: 0|req: 10/10] 192.168.10.50 () {46 vars in 894 bytes} [Wed Apr  8 02:24:00 2020] GET /favicon.ico => generated 2154 bytes in 6 msecs (HTTP/1.1 200) 1 headers in 44 bytes (1 switches on core 0)
*** Starting uWSGI 2.0.18 (64bit) on [Wed Apr  8 02:43:10 2020] ***
compiled with version: 7.5.0 on 07 April 2020 23:31:59
os: Linux-5.0.0-38-generic #41-Ubuntu SMP Tue Dec 3 00:27:35 UTC 2019
nodename: 56c199172e58
machine: x86_64
clock source: unix
detected number of CPU cores: 12
current working directory: /nb/webroot
detected binary path: /usr/local/bin/uwsgi
!!! no internal routing support, rebuild with pcre support !!!
uWSGI running as root, you can use --uid/--gid/--chroot options
*** WARNING: you are running uWSGI as root !!! (use the --uid flag) *** 
*** WARNING: you are running uWSGI without its master process manager ***
your memory page size is 4096 bytes
detected max file descriptor number: 1048576
lock engine: pthread robust mutexes
thunder lock: disabled (you can enable it with --thunder-lock)
uwsgi socket 0 bound to TCP address 0.0.0.0:9201 fd 3
uWSGI running as root, you can use --uid/--gid/--chroot options
*** WARNING: you are running uWSGI as root !!! (use the --uid flag) *** 
Python version: 3.6.9 (default, Nov  7 2019, 10:44:02)  [GCC 8.3.0]
*** Python threads support is disabled. You can enable it with --enable-threads ***
Python main interpreter initialized at 0x55670dae7240
uWSGI running as root, you can use --uid/--gid/--chroot options
*** WARNING: you are running uWSGI as root !!! (use the --uid flag) *** 
your server socket listen backlog is limited to 100 connections
your mercy for graceful operations on workers is 60 seconds
mapped 72904 bytes (71 KB) for 1 cores
*** Operational MODE: single process ***
WSGI app 0 (mountpoint='') ready in 0 seconds on interpreter 0x55670dae7240 pid: 1 (default app)
uWSGI running as root, you can use --uid/--gid/--chroot options
*** WARNING: you are running uWSGI as root !!! (use the --uid flag) *** 
*** uWSGI is running in multiple interpreter mode ***
spawned uWSGI worker 1 (and the only) (pid: 1, cores: 1)
Traceback (most recent call last):
  File "/usr/local/lib/python3.6/dist-packages/pymysql/connections.py", line 583, in connect
    **kwargs)
  File "/usr/lib/python3.6/socket.py", line 724, in create_connection
    raise err
  File "/usr/lib/python3.6/socket.py", line 713, in create_connection
    sock.connect(sa)
ConnectionRefusedError: [Errno 111] Connection refused

During handling of the above exception, another exception occurred:

Traceback (most recent call last):
  File "./index.py", line 20, in application
    init.mysql.connected(init.config['MYSQL']['host'],init.config['MYSQL']['port'],init.config['MYSQL']['database'],init.config['MYSQL']['user'],init.config['MYSQL']['password'])
  File "../lib/MySQLProvider.py", line 10, in connected
    self.connect = pymysql.connect(host=host,user=user,password=password,db=database,port=int(port))
  File "/usr/local/lib/python3.6/dist-packages/pymysql/__init__.py", line 94, in Connect
    return Connection(*args, **kwargs)
  File "/usr/local/lib/python3.6/dist-packages/pymysql/connections.py", line 325, in __init__
    self.connect()
  File "/usr/local/lib/python3.6/dist-packages/pymysql/connections.py", line 630, in connect
    raise exc
pymysql.err.OperationalError: (2003, "Can't connect to MySQL server on 'db' ([Errno 111] Connection refused)")
[pid: 1|app: 0|req: 1/1] 192.168.10.50 () {46 vars in 970 bytes} [Wed Apr  8 02:43:23 2020] GET / => generated 0 bytes in 9 msecs (HTTP/1.1 500) 0 headers in 0 bytes (0 switches on core 0)
Traceback (most recent call last):
  File "/usr/local/lib/python3.6/dist-packages/pymysql/connections.py", line 583, in connect
    **kwargs)
  File "/usr/lib/python3.6/socket.py", line 724, in create_connection
    raise err
  File "/usr/lib/python3.6/socket.py", line 713, in create_connection
    sock.connect(sa)
ConnectionRefusedError: [Errno 111] Connection refused

During handling of the above exception, another exception occurred:

Traceback (most recent call last):
  File "./index.py", line 20, in application
    init.mysql.connected(init.config['MYSQL']['host'],init.config['MYSQL']['port'],init.config['MYSQL']['database'],init.config['MYSQL']['user'],init.config['MYSQL']['password'])
  File "../lib/MySQLProvider.py", line 10, in connected
    self.connect = pymysql.connect(host=host,user=user,password=password,db=database,port=int(port))
  File "/usr/local/lib/python3.6/dist-packages/pymysql/__init__.py", line 94, in Connect
    return Connection(*args, **kwargs)
  File "/usr/local/lib/python3.6/dist-packages/pymysql/connections.py", line 325, in __init__
    self.connect()
  File "/usr/local/lib/python3.6/dist-packages/pymysql/connections.py", line 630, in connect
    raise exc
pymysql.err.OperationalError: (2003, "Can't connect to MySQL server on 'db' ([Errno 111] Connection refused)")
[pid: 1|app: 0|req: 2/2] 192.168.10.50 () {46 vars in 894 bytes} [Wed Apr  8 02:43:23 2020] GET /favicon.ico => generated 0 bytes in 5 msecs (HTTP/1.1 500) 0 headers in 0 bytes (0 switches on core 0)
Traceback (most recent call last):
  File "/usr/local/lib/python3.6/dist-packages/pymysql/connections.py", line 583, in connect
    **kwargs)
  File "/usr/lib/python3.6/socket.py", line 724, in create_connection
    raise err
  File "/usr/lib/python3.6/socket.py", line 713, in create_connection
    sock.connect(sa)
ConnectionRefusedError: [Errno 111] Connection refused

During handling of the above exception, another exception occurred:

Traceback (most recent call last):
  File "./index.py", line 20, in application
    init.mysql.connected(init.config['MYSQL']['host'],init.config['MYSQL']['port'],init.config['MYSQL']['database'],init.config['MYSQL']['user'],init.config['MYSQL']['password'])
  File "../lib/MySQLProvider.py", line 10, in connected
    self.connect = pymysql.connect(host=host,user=user,password=password,db=database,port=int(port))
  File "/usr/local/lib/python3.6/dist-packages/pymysql/__init__.py", line 94, in Connect
    return Connection(*args, **kwargs)
  File "/usr/local/lib/python3.6/dist-packages/pymysql/connections.py", line 325, in __init__
    self.connect()
  File "/usr/local/lib/python3.6/dist-packages/pymysql/connections.py", line 630, in connect
    raise exc
pymysql.err.OperationalError: (2003, "Can't connect to MySQL server on 'db' ([Errno 111] Connection refused)")
[pid: 1|app: 0|req: 3/3] 192.168.10.50 () {46 vars in 970 bytes} [Wed Apr  8 02:43:35 2020] GET / => generated 0 bytes in 4 msecs (HTTP/1.1 500) 0 headers in 0 bytes (0 switches on core 0)
Traceback (most recent call last):
  File "/usr/local/lib/python3.6/dist-packages/pymysql/connections.py", line 583, in connect
    **kwargs)
  File "/usr/lib/python3.6/socket.py", line 724, in create_connection
    raise err
  File "/usr/lib/python3.6/socket.py", line 713, in create_connection
    sock.connect(sa)
ConnectionRefusedError: [Errno 111] Connection refused

During handling of the above exception, another exception occurred:

Traceback (most recent call last):
  File "./index.py", line 20, in application
    init.mysql.connected(init.config['MYSQL']['host'],init.config['MYSQL']['port'],init.config['MYSQL']['database'],init.config['MYSQL']['user'],init.config['MYSQL']['password'])
  File "../lib/MySQLProvider.py", line 10, in connected
    self.connect = pymysql.connect(host=host,user=user,password=password,db=database,port=int(port))
  File "/usr/local/lib/python3.6/dist-packages/pymysql/__init__.py", line 94, in Connect
    return Connection(*args, **kwargs)
  File "/usr/local/lib/python3.6/dist-packages/pymysql/connections.py", line 325, in __init__
    self.connect()
  File "/usr/local/lib/python3.6/dist-packages/pymysql/connections.py", line 630, in connect
    raise exc
pymysql.err.OperationalError: (2003, "Can't connect to MySQL server on 'db' ([Errno 111] Connection refused)")
[pid: 1|app: 0|req: 4/4] 192.168.10.50 () {46 vars in 894 bytes} [Wed Apr  8 02:43:35 2020] GET /favicon.ico => generated 0 bytes in 4 msecs (HTTP/1.1 500) 0 headers in 0 bytes (0 switches on core 0)
Traceback (most recent call last):
  File "/usr/local/lib/python3.6/dist-packages/pymysql/connections.py", line 583, in connect
    **kwargs)
  File "/usr/lib/python3.6/socket.py", line 724, in create_connection
    raise err
  File "/usr/lib/python3.6/socket.py", line 713, in create_connection
    sock.connect(sa)
ConnectionRefusedError: [Errno 111] Connection refused

During handling of the above exception, another exception occurred:

Traceback (most recent call last):
  File "./index.py", line 20, in application
    init.mysql.connected(init.config['MYSQL']['host'],init.config['MYSQL']['port'],init.config['MYSQL']['database'],init.config['MYSQL']['user'],init.config['MYSQL']['password'])
  File "../lib/MySQLProvider.py", line 10, in connected
    self.connect = pymysql.connect(host=host,user=user,password=password,db=database,port=int(port))
  File "/usr/local/lib/python3.6/dist-packages/pymysql/__init__.py", line 94, in Connect
    return Connection(*args, **kwargs)
  File "/usr/local/lib/python3.6/dist-packages/pymysql/connections.py", line 325, in __init__
    self.connect()
  File "/usr/local/lib/python3.6/dist-packages/pymysql/connections.py", line 630, in connect
    raise exc
pymysql.err.OperationalError: (2003, "Can't connect to MySQL server on 'db' ([Errno 111] Connection refused)")
[pid: 1|app: 0|req: 5/5] 192.168.10.50 () {46 vars in 970 bytes} [Wed Apr  8 02:43:35 2020] GET / => generated 0 bytes in 5 msecs (HTTP/1.1 500) 0 headers in 0 bytes (0 switches on core 0)
Traceback (most recent call last):
  File "/usr/local/lib/python3.6/dist-packages/pymysql/connections.py", line 583, in connect
    **kwargs)
  File "/usr/lib/python3.6/socket.py", line 724, in create_connection
    raise err
  File "/usr/lib/python3.6/socket.py", line 713, in create_connection
    sock.connect(sa)
ConnectionRefusedError: [Errno 111] Connection refused

During handling of the above exception, another exception occurred:

Traceback (most recent call last):
  File "./index.py", line 20, in application
    init.mysql.connected(init.config['MYSQL']['host'],init.config['MYSQL']['port'],init.config['MYSQL']['database'],init.config['MYSQL']['user'],init.config['MYSQL']['password'])
  File "../lib/MySQLProvider.py", line 10, in connected
    self.connect = pymysql.connect(host=host,user=user,password=password,db=database,port=int(port))
  File "/usr/local/lib/python3.6/dist-packages/pymysql/__init__.py", line 94, in Connect
    return Connection(*args, **kwargs)
  File "/usr/local/lib/python3.6/dist-packages/pymysql/connections.py", line 325, in __init__
    self.connect()
  File "/usr/local/lib/python3.6/dist-packages/pymysql/connections.py", line 630, in connect
    raise exc
pymysql.err.OperationalError: (2003, "Can't connect to MySQL server on 'db' ([Errno 111] Connection refused)")
[pid: 1|app: 0|req: 6/6] 192.168.10.50 () {46 vars in 894 bytes} [Wed Apr  8 02:43:35 2020] GET /favicon.ico => generated 0 bytes in 2 msecs (HTTP/1.1 500) 0 headers in 0 bytes (0 switches on core 0)
Traceback (most recent call last):
  File "/usr/local/lib/python3.6/dist-packages/pymysql/connections.py", line 583, in connect
    **kwargs)
  File "/usr/lib/python3.6/socket.py", line 724, in create_connection
    raise err
  File "/usr/lib/python3.6/socket.py", line 713, in create_connection
    sock.connect(sa)
ConnectionRefusedError: [Errno 111] Connection refused

During handling of the above exception, another exception occurred:

Traceback (most recent call last):
  File "./index.py", line 20, in application
    init.mysql.connected(init.config['MYSQL']['host'],init.config['MYSQL']['port'],init.config['MYSQL']['database'],init.config['MYSQL']['user'],init.config['MYSQL']['password'])
  File "../lib/MySQLProvider.py", line 10, in connected
    self.connect = pymysql.connect(host=host,user=user,password=password,db=database,port=int(port))
  File "/usr/local/lib/python3.6/dist-packages/pymysql/__init__.py", line 94, in Connect
    return Connection(*args, **kwargs)
  File "/usr/local/lib/python3.6/dist-packages/pymysql/connections.py", line 325, in __init__
    self.connect()
  File "/usr/local/lib/python3.6/dist-packages/pymysql/connections.py", line 630, in connect
    raise exc
pymysql.err.OperationalError: (2003, "Can't connect to MySQL server on 'db' ([Errno 111] Connection refused)")
[pid: 1|app: 0|req: 7/7] 192.168.10.50 () {46 vars in 970 bytes} [Wed Apr  8 02:43:35 2020] GET / => generated 0 bytes in 4 msecs (HTTP/1.1 500) 0 headers in 0 bytes (0 switches on core 0)
Traceback (most recent call last):
  File "/usr/local/lib/python3.6/dist-packages/pymysql/connections.py", line 583, in connect
    **kwargs)
  File "/usr/lib/python3.6/socket.py", line 724, in create_connection
    raise err
  File "/usr/lib/python3.6/socket.py", line 713, in create_connection
    sock.connect(sa)
ConnectionRefusedError: [Errno 111] Connection refused

During handling of the above exception, another exception occurred:

Traceback (most recent call last):
  File "./index.py", line 20, in application
    init.mysql.connected(init.config['MYSQL']['host'],init.config['MYSQL']['port'],init.config['MYSQL']['database'],init.config['MYSQL']['user'],init.config['MYSQL']['password'])
  File "../lib/MySQLProvider.py", line 10, in connected
    self.connect = pymysql.connect(host=host,user=user,password=password,db=database,port=int(port))
  File "/usr/local/lib/python3.6/dist-packages/pymysql/__init__.py", line 94, in Connect
    return Connection(*args, **kwargs)
  File "/usr/local/lib/python3.6/dist-packages/pymysql/connections.py", line 325, in __init__
    self.connect()
  File "/usr/local/lib/python3.6/dist-packages/pymysql/connections.py", line 630, in connect
    raise exc
pymysql.err.OperationalError: (2003, "Can't connect to MySQL server on 'db' ([Errno 111] Connection refused)")
[pid: 1|app: 0|req: 8/8] 192.168.10.50 () {46 vars in 894 bytes} [Wed Apr  8 02:43:35 2020] GET /favicon.ico => generated 0 bytes in 4 msecs (HTTP/1.1 500) 0 headers in 0 bytes (0 switches on core 0)
[pid: 1|app: 0|req: 9/9] 192.168.10.50 () {46 vars in 970 bytes} [Wed Apr  8 02:43:46 2020] GET / => generated 3407 bytes in 98 msecs (HTTP/1.1 200) 1 headers in 44 bytes (1 switches on core 0)
[pid: 1|app: 0|req: 10/10] 192.168.10.50 () {46 vars in 894 bytes} [Wed Apr  8 02:43:46 2020] GET /favicon.ico => generated 2154 bytes in 7 msecs (HTTP/1.1 200) 1 headers in 44 bytes (1 switches on core 0)
*** Starting uWSGI 2.0.18 (64bit) on [Wed Apr  8 02:45:30 2020] ***
compiled with version: 7.5.0 on 07 April 2020 23:31:59
os: Linux-5.0.0-38-generic #41-Ubuntu SMP Tue Dec 3 00:27:35 UTC 2019
nodename: 8bf29b7d71bd
machine: x86_64
clock source: unix
detected number of CPU cores: 12
current working directory: /nb/webroot
detected binary path: /usr/local/bin/uwsgi
!!! no internal routing support, rebuild with pcre support !!!
uWSGI running as root, you can use --uid/--gid/--chroot options
*** WARNING: you are running uWSGI as root !!! (use the --uid flag) *** 
*** WARNING: you are running uWSGI without its master process manager ***
your memory page size is 4096 bytes
detected max file descriptor number: 1048576
lock engine: pthread robust mutexes
thunder lock: disabled (you can enable it with --thunder-lock)
uwsgi socket 0 bound to TCP address 0.0.0.0:9201 fd 3
uWSGI running as root, you can use --uid/--gid/--chroot options
*** WARNING: you are running uWSGI as root !!! (use the --uid flag) *** 
Python version: 3.6.9 (default, Nov  7 2019, 10:44:02)  [GCC 8.3.0]
*** Python threads support is disabled. You can enable it with --enable-threads ***
Python main interpreter initialized at 0x5636833e1240
uWSGI running as root, you can use --uid/--gid/--chroot options
*** WARNING: you are running uWSGI as root !!! (use the --uid flag) *** 
your server socket listen backlog is limited to 100 connections
your mercy for graceful operations on workers is 60 seconds
mapped 72904 bytes (71 KB) for 1 cores
*** Operational MODE: single process ***
WSGI app 0 (mountpoint='') ready in 1 seconds on interpreter 0x5636833e1240 pid: 1 (default app)
uWSGI running as root, you can use --uid/--gid/--chroot options
*** WARNING: you are running uWSGI as root !!! (use the --uid flag) *** 
*** uWSGI is running in multiple interpreter mode ***
spawned uWSGI worker 1 (and the only) (pid: 1, cores: 1)
Traceback (most recent call last):
  File "/usr/local/lib/python3.6/dist-packages/pymysql/connections.py", line 583, in connect
    **kwargs)
  File "/usr/lib/python3.6/socket.py", line 724, in create_connection
    raise err
  File "/usr/lib/python3.6/socket.py", line 713, in create_connection
    sock.connect(sa)
ConnectionRefusedError: [Errno 111] Connection refused

During handling of the above exception, another exception occurred:

Traceback (most recent call last):
  File "./index.py", line 20, in application
    init.mysql.connected(init.config['MYSQL']['host'],init.config['MYSQL']['port'],init.config['MYSQL']['database'],init.config['MYSQL']['user'],init.config['MYSQL']['password'])
  File "../lib/MySQLProvider.py", line 10, in connected
    self.connect = pymysql.connect(host=host,user=user,password=password,db=database,port=int(port))
  File "/usr/local/lib/python3.6/dist-packages/pymysql/__init__.py", line 94, in Connect
    return Connection(*args, **kwargs)
  File "/usr/local/lib/python3.6/dist-packages/pymysql/connections.py", line 325, in __init__
    self.connect()
  File "/usr/local/lib/python3.6/dist-packages/pymysql/connections.py", line 630, in connect
    raise exc
pymysql.err.OperationalError: (2003, "Can't connect to MySQL server on 'db' ([Errno 111] Connection refused)")
[pid: 1|app: 0|req: 1/1] 192.168.10.50 () {46 vars in 970 bytes} [Wed Apr  8 02:45:47 2020] GET / => generated 0 bytes in 8 msecs (HTTP/1.1 500) 0 headers in 0 bytes (0 switches on core 0)
Traceback (most recent call last):
  File "/usr/local/lib/python3.6/dist-packages/pymysql/connections.py", line 583, in connect
    **kwargs)
  File "/usr/lib/python3.6/socket.py", line 724, in create_connection
    raise err
  File "/usr/lib/python3.6/socket.py", line 713, in create_connection
    sock.connect(sa)
ConnectionRefusedError: [Errno 111] Connection refused

During handling of the above exception, another exception occurred:

Traceback (most recent call last):
  File "./index.py", line 20, in application
    init.mysql.connected(init.config['MYSQL']['host'],init.config['MYSQL']['port'],init.config['MYSQL']['database'],init.config['MYSQL']['user'],init.config['MYSQL']['password'])
  File "../lib/MySQLProvider.py", line 10, in connected
    self.connect = pymysql.connect(host=host,user=user,password=password,db=database,port=int(port))
  File "/usr/local/lib/python3.6/dist-packages/pymysql/__init__.py", line 94, in Connect
    return Connection(*args, **kwargs)
  File "/usr/local/lib/python3.6/dist-packages/pymysql/connections.py", line 325, in __init__
    self.connect()
  File "/usr/local/lib/python3.6/dist-packages/pymysql/connections.py", line 630, in connect
    raise exc
pymysql.err.OperationalError: (2003, "Can't connect to MySQL server on 'db' ([Errno 111] Connection refused)")
[pid: 1|app: 0|req: 2/2] 192.168.10.50 () {46 vars in 894 bytes} [Wed Apr  8 02:45:47 2020] GET /favicon.ico => generated 0 bytes in 4 msecs (HTTP/1.1 500) 0 headers in 0 bytes (0 switches on core 0)
Traceback (most recent call last):
  File "/usr/local/lib/python3.6/dist-packages/pymysql/connections.py", line 583, in connect
    **kwargs)
  File "/usr/lib/python3.6/socket.py", line 724, in create_connection
    raise err
  File "/usr/lib/python3.6/socket.py", line 713, in create_connection
    sock.connect(sa)
ConnectionRefusedError: [Errno 111] Connection refused

During handling of the above exception, another exception occurred:

Traceback (most recent call last):
  File "./index.py", line 20, in application
    init.mysql.connected(init.config['MYSQL']['host'],init.config['MYSQL']['port'],init.config['MYSQL']['database'],init.config['MYSQL']['user'],init.config['MYSQL']['password'])
  File "../lib/MySQLProvider.py", line 10, in connected
    self.connect = pymysql.connect(host=host,user=user,password=password,db=database,port=int(port))
  File "/usr/local/lib/python3.6/dist-packages/pymysql/__init__.py", line 94, in Connect
    return Connection(*args, **kwargs)
  File "/usr/local/lib/python3.6/dist-packages/pymysql/connections.py", line 325, in __init__
    self.connect()
  File "/usr/local/lib/python3.6/dist-packages/pymysql/connections.py", line 630, in connect
    raise exc
pymysql.err.OperationalError: (2003, "Can't connect to MySQL server on 'db' ([Errno 111] Connection refused)")
[pid: 1|app: 0|req: 3/3] 192.168.10.50 () {46 vars in 970 bytes} [Wed Apr  8 02:45:49 2020] GET / => generated 0 bytes in 4 msecs (HTTP/1.1 500) 0 headers in 0 bytes (0 switches on core 0)
Traceback (most recent call last):
  File "/usr/local/lib/python3.6/dist-packages/pymysql/connections.py", line 583, in connect
    **kwargs)
  File "/usr/lib/python3.6/socket.py", line 724, in create_connection
    raise err
  File "/usr/lib/python3.6/socket.py", line 713, in create_connection
    sock.connect(sa)
ConnectionRefusedError: [Errno 111] Connection refused

During handling of the above exception, another exception occurred:

Traceback (most recent call last):
  File "./index.py", line 20, in application
    init.mysql.connected(init.config['MYSQL']['host'],init.config['MYSQL']['port'],init.config['MYSQL']['database'],init.config['MYSQL']['user'],init.config['MYSQL']['password'])
  File "../lib/MySQLProvider.py", line 10, in connected
    self.connect = pymysql.connect(host=host,user=user,password=password,db=database,port=int(port))
  File "/usr/local/lib/python3.6/dist-packages/pymysql/__init__.py", line 94, in Connect
    return Connection(*args, **kwargs)
  File "/usr/local/lib/python3.6/dist-packages/pymysql/connections.py", line 325, in __init__
    self.connect()
  File "/usr/local/lib/python3.6/dist-packages/pymysql/connections.py", line 630, in connect
    raise exc
pymysql.err.OperationalError: (2003, "Can't connect to MySQL server on 'db' ([Errno 111] Connection refused)")
[pid: 1|app: 0|req: 4/4] 192.168.10.50 () {46 vars in 894 bytes} [Wed Apr  8 02:45:49 2020] GET /favicon.ico => generated 0 bytes in 2 msecs (HTTP/1.1 500) 0 headers in 0 bytes (0 switches on core 0)
Traceback (most recent call last):
  File "/usr/local/lib/python3.6/dist-packages/pymysql/connections.py", line 583, in connect
    **kwargs)
  File "/usr/lib/python3.6/socket.py", line 724, in create_connection
    raise err
  File "/usr/lib/python3.6/socket.py", line 713, in create_connection
    sock.connect(sa)
ConnectionRefusedError: [Errno 111] Connection refused

During handling of the above exception, another exception occurred:

Traceback (most recent call last):
  File "./index.py", line 20, in application
    init.mysql.connected(init.config['MYSQL']['host'],init.config['MYSQL']['port'],init.config['MYSQL']['database'],init.config['MYSQL']['user'],init.config['MYSQL']['password'])
  File "../lib/MySQLProvider.py", line 10, in connected
    self.connect = pymysql.connect(host=host,user=user,password=password,db=database,port=int(port))
  File "/usr/local/lib/python3.6/dist-packages/pymysql/__init__.py", line 94, in Connect
    return Connection(*args, **kwargs)
  File "/usr/local/lib/python3.6/dist-packages/pymysql/connections.py", line 325, in __init__
    self.connect()
  File "/usr/local/lib/python3.6/dist-packages/pymysql/connections.py", line 630, in connect
    raise exc
pymysql.err.OperationalError: (2003, "Can't connect to MySQL server on 'db' ([Errno 111] Connection refused)")
[pid: 1|app: 0|req: 5/5] 192.168.10.50 () {46 vars in 970 bytes} [Wed Apr  8 02:45:52 2020] GET / => generated 0 bytes in 4 msecs (HTTP/1.1 500) 0 headers in 0 bytes (0 switches on core 0)
Traceback (most recent call last):
  File "/usr/local/lib/python3.6/dist-packages/pymysql/connections.py", line 583, in connect
    **kwargs)
  File "/usr/lib/python3.6/socket.py", line 724, in create_connection
    raise err
  File "/usr/lib/python3.6/socket.py", line 713, in create_connection
    sock.connect(sa)
ConnectionRefusedError: [Errno 111] Connection refused

During handling of the above exception, another exception occurred:

Traceback (most recent call last):
  File "./index.py", line 20, in application
    init.mysql.connected(init.config['MYSQL']['host'],init.config['MYSQL']['port'],init.config['MYSQL']['database'],init.config['MYSQL']['user'],init.config['MYSQL']['password'])
  File "../lib/MySQLProvider.py", line 10, in connected
    self.connect = pymysql.connect(host=host,user=user,password=password,db=database,port=int(port))
  File "/usr/local/lib/python3.6/dist-packages/pymysql/__init__.py", line 94, in Connect
    return Connection(*args, **kwargs)
  File "/usr/local/lib/python3.6/dist-packages/pymysql/connections.py", line 325, in __init__
    self.connect()
  File "/usr/local/lib/python3.6/dist-packages/pymysql/connections.py", line 630, in connect
    raise exc
pymysql.err.OperationalError: (2003, "Can't connect to MySQL server on 'db' ([Errno 111] Connection refused)")
[pid: 1|app: 0|req: 6/6] 192.168.10.50 () {46 vars in 894 bytes} [Wed Apr  8 02:45:52 2020] GET /favicon.ico => generated 0 bytes in 3 msecs (HTTP/1.1 500) 0 headers in 0 bytes (0 switches on core 0)
Traceback (most recent call last):
  File "/usr/local/lib/python3.6/dist-packages/pymysql/connections.py", line 583, in connect
    **kwargs)
  File "/usr/lib/python3.6/socket.py", line 724, in create_connection
    raise err
  File "/usr/lib/python3.6/socket.py", line 713, in create_connection
    sock.connect(sa)
ConnectionRefusedError: [Errno 111] Connection refused

During handling of the above exception, another exception occurred:

Traceback (most recent call last):
  File "./index.py", line 20, in application
    init.mysql.connected(init.config['MYSQL']['host'],init.config['MYSQL']['port'],init.config['MYSQL']['database'],init.config['MYSQL']['user'],init.config['MYSQL']['password'])
  File "../lib/MySQLProvider.py", line 10, in connected
    self.connect = pymysql.connect(host=host,user=user,password=password,db=database,port=int(port))
  File "/usr/local/lib/python3.6/dist-packages/pymysql/__init__.py", line 94, in Connect
    return Connection(*args, **kwargs)
  File "/usr/local/lib/python3.6/dist-packages/pymysql/connections.py", line 325, in __init__
    self.connect()
  File "/usr/local/lib/python3.6/dist-packages/pymysql/connections.py", line 630, in connect
    raise exc
pymysql.err.OperationalError: (2003, "Can't connect to MySQL server on 'db' ([Errno 111] Connection refused)")
[pid: 1|app: 0|req: 7/7] 192.168.10.50 () {46 vars in 970 bytes} [Wed Apr  8 02:45:53 2020] GET / => generated 0 bytes in 4 msecs (HTTP/1.1 500) 0 headers in 0 bytes (0 switches on core 0)
Traceback (most recent call last):
  File "/usr/local/lib/python3.6/dist-packages/pymysql/connections.py", line 583, in connect
    **kwargs)
  File "/usr/lib/python3.6/socket.py", line 724, in create_connection
    raise err
  File "/usr/lib/python3.6/socket.py", line 713, in create_connection
    sock.connect(sa)
ConnectionRefusedError: [Errno 111] Connection refused

During handling of the above exception, another exception occurred:

Traceback (most recent call last):
  File "./index.py", line 20, in application
    init.mysql.connected(init.config['MYSQL']['host'],init.config['MYSQL']['port'],init.config['MYSQL']['database'],init.config['MYSQL']['user'],init.config['MYSQL']['password'])
  File "../lib/MySQLProvider.py", line 10, in connected
    self.connect = pymysql.connect(host=host,user=user,password=password,db=database,port=int(port))
  File "/usr/local/lib/python3.6/dist-packages/pymysql/__init__.py", line 94, in Connect
    return Connection(*args, **kwargs)
  File "/usr/local/lib/python3.6/dist-packages/pymysql/connections.py", line 325, in __init__
    self.connect()
  File "/usr/local/lib/python3.6/dist-packages/pymysql/connections.py", line 630, in connect
    raise exc
pymysql.err.OperationalError: (2003, "Can't connect to MySQL server on 'db' ([Errno 111] Connection refused)")
[pid: 1|app: 0|req: 8/8] 192.168.10.50 () {46 vars in 894 bytes} [Wed Apr  8 02:45:53 2020] GET /favicon.ico => generated 0 bytes in 4 msecs (HTTP/1.1 500) 0 headers in 0 bytes (0 switches on core 0)
[pid: 1|app: 0|req: 9/9] 192.168.10.50 () {46 vars in 970 bytes} [Wed Apr  8 02:45:57 2020] GET / => generated 3407 bytes in 112 msecs (HTTP/1.1 200) 1 headers in 44 bytes (1 switches on core 0)
[pid: 1|app: 0|req: 10/10] 192.168.10.50 () {46 vars in 894 bytes} [Wed Apr  8 02:45:57 2020] GET /favicon.ico => generated 2154 bytes in 7 msecs (HTTP/1.1 200) 1 headers in 44 bytes (1 switches on core 0)
*** Starting uWSGI 2.0.18 (64bit) on [Wed Apr  8 02:48:44 2020] ***
compiled with version: 7.5.0 on 07 April 2020 23:31:59
os: Linux-5.0.0-38-generic #41-Ubuntu SMP Tue Dec 3 00:27:35 UTC 2019
nodename: 9f37fead55bc
machine: x86_64
clock source: unix
detected number of CPU cores: 12
current working directory: /nb/webroot
detected binary path: /usr/local/bin/uwsgi
!!! no internal routing support, rebuild with pcre support !!!
uWSGI running as root, you can use --uid/--gid/--chroot options
*** WARNING: you are running uWSGI as root !!! (use the --uid flag) *** 
*** WARNING: you are running uWSGI without its master process manager ***
your memory page size is 4096 bytes
detected max file descriptor number: 1048576
lock engine: pthread robust mutexes
thunder lock: disabled (you can enable it with --thunder-lock)
uwsgi socket 0 bound to TCP address 0.0.0.0:9201 fd 3
uWSGI running as root, you can use --uid/--gid/--chroot options
*** WARNING: you are running uWSGI as root !!! (use the --uid flag) *** 
Python version: 3.6.9 (default, Nov  7 2019, 10:44:02)  [GCC 8.3.0]
*** Python threads support is disabled. You can enable it with --enable-threads ***
Python main interpreter initialized at 0x557ca2340240
uWSGI running as root, you can use --uid/--gid/--chroot options
*** WARNING: you are running uWSGI as root !!! (use the --uid flag) *** 
your server socket listen backlog is limited to 100 connections
your mercy for graceful operations on workers is 60 seconds
mapped 72904 bytes (71 KB) for 1 cores
*** Operational MODE: single process ***
WSGI app 0 (mountpoint='') ready in 0 seconds on interpreter 0x557ca2340240 pid: 1 (default app)
uWSGI running as root, you can use --uid/--gid/--chroot options
*** WARNING: you are running uWSGI as root !!! (use the --uid flag) *** 
*** uWSGI is running in multiple interpreter mode ***
spawned uWSGI worker 1 (and the only) (pid: 1, cores: 1)
[pid: 1|app: 0|req: 1/1] 192.168.10.50 () {46 vars in 970 bytes} [Wed Apr  8 02:49:12 2020] GET / => generated 3407 bytes in 107 msecs (HTTP/1.1 200) 1 headers in 44 bytes (1 switches on core 0)
[pid: 1|app: 0|req: 2/2] 192.168.10.50 () {46 vars in 894 bytes} [Wed Apr  8 02:49:13 2020] GET /favicon.ico => generated 2154 bytes in 7 msecs (HTTP/1.1 200) 1 headers in 44 bytes (1 switches on core 0)
[pid: 1|app: 0|req: 3/3] 192.168.10.50 () {46 vars in 970 bytes} [Wed Apr  8 02:49:13 2020] GET / => generated 3407 bytes in 14 msecs (HTTP/1.1 200) 1 headers in 44 bytes (1 switches on core 0)
[pid: 1|app: 0|req: 4/4] 192.168.10.50 () {46 vars in 894 bytes} [Wed Apr  8 02:49:13 2020] GET /favicon.ico => generated 2154 bytes in 6 msecs (HTTP/1.1 200) 1 headers in 44 bytes (1 switches on core 0)
[pid: 1|app: 0|req: 5/5] 192.168.10.50 () {44 vars in 939 bytes} [Wed Apr  8 02:49:37 2020] GET / => generated 3966 bytes in 12 msecs (HTTP/1.1 200) 1 headers in 44 bytes (1 switches on core 0)
[pid: 1|app: 0|req: 6/6] 192.168.10.50 () {42 vars in 841 bytes} [Wed Apr  8 02:49:37 2020] GET /favicon.ico => generated 2154 bytes in 6 msecs (HTTP/1.1 200) 1 headers in 44 bytes (1 switches on core 0)
*** Starting uWSGI 2.0.18 (64bit) on [Wed Apr  8 03:01:10 2020] ***
compiled with version: 7.5.0 on 07 April 2020 23:31:59
os: Linux-5.0.0-38-generic #41-Ubuntu SMP Tue Dec 3 00:27:35 UTC 2019
nodename: 9f37fead55bc
machine: x86_64
clock source: unix
detected number of CPU cores: 12
current working directory: /nb/webroot
detected binary path: /usr/local/bin/uwsgi
!!! no internal routing support, rebuild with pcre support !!!
uWSGI running as root, you can use --uid/--gid/--chroot options
*** WARNING: you are running uWSGI as root !!! (use the --uid flag) *** 
*** WARNING: you are running uWSGI without its master process manager ***
your memory page size is 4096 bytes
detected max file descriptor number: 1048576
lock engine: pthread robust mutexes
thunder lock: disabled (you can enable it with --thunder-lock)
uwsgi socket 0 bound to TCP address 0.0.0.0:9201 fd 3
uWSGI running as root, you can use --uid/--gid/--chroot options
*** WARNING: you are running uWSGI as root !!! (use the --uid flag) *** 
Python version: 3.6.9 (default, Nov  7 2019, 10:44:02)  [GCC 8.3.0]
*** Python threads support is disabled. You can enable it with --enable-threads ***
Python main interpreter initialized at 0x560d844d7240
uWSGI running as root, you can use --uid/--gid/--chroot options
*** WARNING: you are running uWSGI as root !!! (use the --uid flag) *** 
your server socket listen backlog is limited to 100 connections
your mercy for graceful operations on workers is 60 seconds
mapped 72904 bytes (71 KB) for 1 cores
*** Operational MODE: single process ***
WSGI app 0 (mountpoint='') ready in 0 seconds on interpreter 0x560d844d7240 pid: 1 (default app)
uWSGI running as root, you can use --uid/--gid/--chroot options
*** WARNING: you are running uWSGI as root !!! (use the --uid flag) *** 
*** uWSGI is running in multiple interpreter mode ***
spawned uWSGI worker 1 (and the only) (pid: 1, cores: 1)
[pid: 1|app: 0|req: 1/1] 192.168.10.50 () {46 vars in 970 bytes} [Wed Apr  8 03:01:23 2020] GET / => generated 3966 bytes in 105 msecs (HTTP/1.1 200) 1 headers in 44 bytes (1 switches on core 0)
[pid: 1|app: 0|req: 2/2] 192.168.10.50 () {46 vars in 894 bytes} [Wed Apr  8 03:01:23 2020] GET /favicon.ico => generated 2154 bytes in 7 msecs (HTTP/1.1 200) 1 headers in 44 bytes (1 switches on core 0)
[pid: 1|app: 0|req: 3/3] 192.168.10.50 () {46 vars in 970 bytes} [Wed Apr  8 03:01:24 2020] GET / => generated 3966 bytes in 12 msecs (HTTP/1.1 200) 1 headers in 44 bytes (1 switches on core 0)
[pid: 1|app: 0|req: 4/4] 192.168.10.50 () {46 vars in 894 bytes} [Wed Apr  8 03:01:24 2020] GET /favicon.ico => generated 2154 bytes in 6 msecs (HTTP/1.1 200) 1 headers in 44 bytes (1 switches on core 0)
[pid: 1|app: 0|req: 5/5] 192.168.10.50 () {46 vars in 970 bytes} [Wed Apr  8 03:01:24 2020] GET / => generated 3966 bytes in 11 msecs (HTTP/1.1 200) 1 headers in 44 bytes (1 switches on core 0)
[pid: 1|app: 0|req: 6/6] 192.168.10.50 () {46 vars in 894 bytes} [Wed Apr  8 03:01:24 2020] GET /favicon.ico => generated 2154 bytes in 6 msecs (HTTP/1.1 200) 1 headers in 44 bytes (1 switches on core 0)
[pid: 1|app: 0|req: 7/7] 192.168.10.50 () {46 vars in 970 bytes} [Wed Apr  8 03:01:24 2020] GET / => generated 3966 bytes in 11 msecs (HTTP/1.1 200) 1 headers in 44 bytes (1 switches on core 0)
[pid: 1|app: 0|req: 8/8] 192.168.10.50 () {46 vars in 894 bytes} [Wed Apr  8 03:01:24 2020] GET /favicon.ico => generated 2154 bytes in 6 msecs (HTTP/1.1 200) 1 headers in 44 bytes (1 switches on core 0)
[pid: 1|app: 0|req: 9/9] 192.168.10.50 () {46 vars in 970 bytes} [Wed Apr  8 03:01:25 2020] GET / => generated 3966 bytes in 12 msecs (HTTP/1.1 200) 1 headers in 44 bytes (1 switches on core 0)
[pid: 1|app: 0|req: 10/10] 192.168.10.50 () {46 vars in 894 bytes} [Wed Apr  8 03:01:25 2020] GET /favicon.ico => generated 2154 bytes in 6 msecs (HTTP/1.1 200) 1 headers in 44 bytes (1 switches on core 0)
[pid: 1|app: 0|req: 11/11] 192.168.10.50 () {46 vars in 970 bytes} [Wed Apr  8 03:01:25 2020] GET / => generated 3966 bytes in 12 msecs (HTTP/1.1 200) 1 headers in 44 bytes (1 switches on core 0)
[pid: 1|app: 0|req: 12/12] 192.168.10.50 () {46 vars in 894 bytes} [Wed Apr  8 03:01:25 2020] GET /favicon.ico => generated 2154 bytes in 6 msecs (HTTP/1.1 200) 1 headers in 44 bytes (1 switches on core 0)
[pid: 1|app: 0|req: 13/13] 192.168.10.50 () {46 vars in 970 bytes} [Wed Apr  8 03:01:25 2020] GET / => generated 3966 bytes in 13 msecs (HTTP/1.1 200) 1 headers in 44 bytes (1 switches on core 0)
[pid: 1|app: 0|req: 14/14] 192.168.10.50 () {46 vars in 894 bytes} [Wed Apr  8 03:01:25 2020] GET /favicon.ico => generated 2154 bytes in 6 msecs (HTTP/1.1 200) 1 headers in 44 bytes (1 switches on core 0)
[pid: 1|app: 0|req: 15/15] 192.168.10.50 () {46 vars in 970 bytes} [Wed Apr  8 03:01:25 2020] GET / => generated 3966 bytes in 13 msecs (HTTP/1.1 200) 1 headers in 44 bytes (1 switches on core 0)
[pid: 1|app: 0|req: 16/16] 192.168.10.50 () {46 vars in 894 bytes} [Wed Apr  8 03:01:25 2020] GET /favicon.ico => generated 2154 bytes in 6 msecs (HTTP/1.1 200) 1 headers in 44 bytes (1 switches on core 0)
[pid: 1|app: 0|req: 17/17] 192.168.10.50 () {44 vars in 980 bytes} [Wed Apr  8 03:01:28 2020] GET /cpe_commands?cpe_id=1 => generated 6000 bytes in 23 msecs (HTTP/1.1 200) 1 headers in 44 bytes (1 switches on core 0)
[pid: 1|app: 0|req: 18/18] 192.168.10.50 () {42 vars in 862 bytes} [Wed Apr  8 03:01:28 2020] GET /favicon.ico => generated 2154 bytes in 6 msecs (HTTP/1.1 200) 1 headers in 44 bytes (1 switches on core 0)
[pid: 1|app: 0|req: 19/19] 192.168.10.50 () {44 vars in 960 bytes} [Wed Apr  8 03:01:30 2020] GET / => generated 3966 bytes in 13 msecs (HTTP/1.1 200) 1 headers in 44 bytes (1 switches on core 0)
[pid: 1|app: 0|req: 20/20] 192.168.10.50 () {42 vars in 841 bytes} [Wed Apr  8 03:01:30 2020] GET /favicon.ico => generated 2154 bytes in 6 msecs (HTTP/1.1 200) 1 headers in 44 bytes (1 switches on core 0)
*** Starting uWSGI 2.0.18 (64bit) on [Wed Apr  8 03:01:41 2020] ***
compiled with version: 7.5.0 on 07 April 2020 23:31:59
os: Linux-5.0.0-38-generic #41-Ubuntu SMP Tue Dec 3 00:27:35 UTC 2019
nodename: 9f37fead55bc
machine: x86_64
clock source: unix
detected number of CPU cores: 12
current working directory: /nb/webroot
detected binary path: /usr/local/bin/uwsgi
!!! no internal routing support, rebuild with pcre support !!!
uWSGI running as root, you can use --uid/--gid/--chroot options
*** WARNING: you are running uWSGI as root !!! (use the --uid flag) *** 
*** WARNING: you are running uWSGI without its master process manager ***
your memory page size is 4096 bytes
detected max file descriptor number: 1048576
lock engine: pthread robust mutexes
thunder lock: disabled (you can enable it with --thunder-lock)
uwsgi socket 0 bound to TCP address 0.0.0.0:9201 fd 3
uWSGI running as root, you can use --uid/--gid/--chroot options
*** WARNING: you are running uWSGI as root !!! (use the --uid flag) *** 
Python version: 3.6.9 (default, Nov  7 2019, 10:44:02)  [GCC 8.3.0]
*** Python threads support is disabled. You can enable it with --enable-threads ***
Python main interpreter initialized at 0x55b0651cb240
uWSGI running as root, you can use --uid/--gid/--chroot options
*** WARNING: you are running uWSGI as root !!! (use the --uid flag) *** 
your server socket listen backlog is limited to 100 connections
your mercy for graceful operations on workers is 60 seconds
mapped 72904 bytes (71 KB) for 1 cores
*** Operational MODE: single process ***
WSGI app 0 (mountpoint='') ready in 0 seconds on interpreter 0x55b0651cb240 pid: 1 (default app)
uWSGI running as root, you can use --uid/--gid/--chroot options
*** WARNING: you are running uWSGI as root !!! (use the --uid flag) *** 
*** uWSGI is running in multiple interpreter mode ***
spawned uWSGI worker 1 (and the only) (pid: 1, cores: 1)
[pid: 1|app: 0|req: 1/1] 192.168.10.50 () {46 vars in 991 bytes} [Wed Apr  8 03:01:44 2020] GET / => generated 3966 bytes in 105 msecs (HTTP/1.1 200) 1 headers in 44 bytes (1 switches on core 0)
[pid: 1|app: 0|req: 2/2] 192.168.10.50 () {46 vars in 894 bytes} [Wed Apr  8 03:01:44 2020] GET /favicon.ico => generated 2154 bytes in 7 msecs (HTTP/1.1 200) 1 headers in 44 bytes (1 switches on core 0)
[pid: 1|app: 0|req: 3/3] 192.168.10.50 () {46 vars in 991 bytes} [Wed Apr  8 03:01:45 2020] GET / => generated 3966 bytes in 11 msecs (HTTP/1.1 200) 1 headers in 44 bytes (1 switches on core 0)
[pid: 1|app: 0|req: 4/4] 192.168.10.50 () {46 vars in 894 bytes} [Wed Apr  8 03:01:45 2020] GET /favicon.ico => generated 2154 bytes in 6 msecs (HTTP/1.1 200) 1 headers in 44 bytes (1 switches on core 0)
[pid: 1|app: 0|req: 5/5] 192.168.10.50 () {44 vars in 869 bytes} [Wed Apr  8 03:01:55 2020] GET /cpe_inform_ajax?cpe_id=1 => generated 2497 bytes in 3 msecs (HTTP/1.1 200) 1 headers in 44 bytes (1 switches on core 0)
*** Starting uWSGI 2.0.18 (64bit) on [Wed Apr  8 03:12:23 2020] ***
compiled with version: 7.5.0 on 07 April 2020 23:31:59
os: Linux-5.0.0-38-generic #41-Ubuntu SMP Tue Dec 3 00:27:35 UTC 2019
nodename: 818033d7d797
machine: x86_64
clock source: unix
detected number of CPU cores: 12
current working directory: /nb/webroot
detected binary path: /usr/local/bin/uwsgi
!!! no internal routing support, rebuild with pcre support !!!
uWSGI running as root, you can use --uid/--gid/--chroot options
*** WARNING: you are running uWSGI as root !!! (use the --uid flag) *** 
*** WARNING: you are running uWSGI without its master process manager ***
your memory page size is 4096 bytes
detected max file descriptor number: 1048576
lock engine: pthread robust mutexes
thunder lock: disabled (you can enable it with --thunder-lock)
uwsgi socket 0 bound to TCP address 0.0.0.0:9201 fd 3
uWSGI running as root, you can use --uid/--gid/--chroot options
*** WARNING: you are running uWSGI as root !!! (use the --uid flag) *** 
Python version: 3.6.9 (default, Nov  7 2019, 10:44:02)  [GCC 8.3.0]
*** Python threads support is disabled. You can enable it with --enable-threads ***
Python main interpreter initialized at 0x555b75b4b240
uWSGI running as root, you can use --uid/--gid/--chroot options
*** WARNING: you are running uWSGI as root !!! (use the --uid flag) *** 
your server socket listen backlog is limited to 100 connections
your mercy for graceful operations on workers is 60 seconds
mapped 72904 bytes (71 KB) for 1 cores
*** Operational MODE: single process ***
WSGI app 0 (mountpoint='') ready in 0 seconds on interpreter 0x555b75b4b240 pid: 1 (default app)
uWSGI running as root, you can use --uid/--gid/--chroot options
*** WARNING: you are running uWSGI as root !!! (use the --uid flag) *** 
*** uWSGI is running in multiple interpreter mode ***
spawned uWSGI worker 1 (and the only) (pid: 1, cores: 1)
Traceback (most recent call last):
  File "/usr/local/lib/python3.6/dist-packages/pymysql/connections.py", line 583, in connect
    **kwargs)
  File "/usr/lib/python3.6/socket.py", line 724, in create_connection
    raise err
  File "/usr/lib/python3.6/socket.py", line 713, in create_connection
    sock.connect(sa)
ConnectionRefusedError: [Errno 111] Connection refused

During handling of the above exception, another exception occurred:

Traceback (most recent call last):
  File "./index.py", line 20, in application
    init.mysql.connected(init.config['MYSQL']['host'],init.config['MYSQL']['port'],init.config['MYSQL']['database'],init.config['MYSQL']['user'],init.config['MYSQL']['password'])
  File "../lib/MySQLProvider.py", line 10, in connected
    self.connect = pymysql.connect(host=host,user=user,password=password,db=database,port=int(port))
  File "/usr/local/lib/python3.6/dist-packages/pymysql/__init__.py", line 94, in Connect
    return Connection(*args, **kwargs)
  File "/usr/local/lib/python3.6/dist-packages/pymysql/connections.py", line 325, in __init__
    self.connect()
  File "/usr/local/lib/python3.6/dist-packages/pymysql/connections.py", line 630, in connect
    raise exc
pymysql.err.OperationalError: (2003, "Can't connect to MySQL server on 'db' ([Errno 111] Connection refused)")
[pid: 1|app: 0|req: 1/1] 192.168.10.50 () {46 vars in 991 bytes} [Wed Apr  8 03:12:32 2020] GET / => generated 0 bytes in 9 msecs (HTTP/1.1 500) 0 headers in 0 bytes (0 switches on core 0)
Traceback (most recent call last):
  File "/usr/local/lib/python3.6/dist-packages/pymysql/connections.py", line 583, in connect
    **kwargs)
  File "/usr/lib/python3.6/socket.py", line 724, in create_connection
    raise err
  File "/usr/lib/python3.6/socket.py", line 713, in create_connection
    sock.connect(sa)
ConnectionRefusedError: [Errno 111] Connection refused

During handling of the above exception, another exception occurred:

Traceback (most recent call last):
  File "./index.py", line 20, in application
    init.mysql.connected(init.config['MYSQL']['host'],init.config['MYSQL']['port'],init.config['MYSQL']['database'],init.config['MYSQL']['user'],init.config['MYSQL']['password'])
  File "../lib/MySQLProvider.py", line 10, in connected
    self.connect = pymysql.connect(host=host,user=user,password=password,db=database,port=int(port))
  File "/usr/local/lib/python3.6/dist-packages/pymysql/__init__.py", line 94, in Connect
    return Connection(*args, **kwargs)
  File "/usr/local/lib/python3.6/dist-packages/pymysql/connections.py", line 325, in __init__
    self.connect()
  File "/usr/local/lib/python3.6/dist-packages/pymysql/connections.py", line 630, in connect
    raise exc
pymysql.err.OperationalError: (2003, "Can't connect to MySQL server on 'db' ([Errno 111] Connection refused)")
[pid: 1|app: 0|req: 2/2] 192.168.10.50 () {46 vars in 894 bytes} [Wed Apr  8 03:12:33 2020] GET /favicon.ico => generated 0 bytes in 4 msecs (HTTP/1.1 500) 0 headers in 0 bytes (0 switches on core 0)
Traceback (most recent call last):
  File "/usr/local/lib/python3.6/dist-packages/pymysql/connections.py", line 583, in connect
    **kwargs)
  File "/usr/lib/python3.6/socket.py", line 724, in create_connection
    raise err
  File "/usr/lib/python3.6/socket.py", line 713, in create_connection
    sock.connect(sa)
ConnectionRefusedError: [Errno 111] Connection refused

During handling of the above exception, another exception occurred:

Traceback (most recent call last):
  File "./index.py", line 20, in application
    init.mysql.connected(init.config['MYSQL']['host'],init.config['MYSQL']['port'],init.config['MYSQL']['database'],init.config['MYSQL']['user'],init.config['MYSQL']['password'])
  File "../lib/MySQLProvider.py", line 10, in connected
    self.connect = pymysql.connect(host=host,user=user,password=password,db=database,port=int(port))
  File "/usr/local/lib/python3.6/dist-packages/pymysql/__init__.py", line 94, in Connect
    return Connection(*args, **kwargs)
  File "/usr/local/lib/python3.6/dist-packages/pymysql/connections.py", line 325, in __init__
    self.connect()
  File "/usr/local/lib/python3.6/dist-packages/pymysql/connections.py", line 630, in connect
    raise exc
pymysql.err.OperationalError: (2003, "Can't connect to MySQL server on 'db' ([Errno 111] Connection refused)")
[pid: 1|app: 0|req: 3/3] 192.168.10.50 () {46 vars in 991 bytes} [Wed Apr  8 03:12:33 2020] GET / => generated 0 bytes in 4 msecs (HTTP/1.1 500) 0 headers in 0 bytes (0 switches on core 0)
Traceback (most recent call last):
  File "/usr/local/lib/python3.6/dist-packages/pymysql/connections.py", line 583, in connect
    **kwargs)
  File "/usr/lib/python3.6/socket.py", line 724, in create_connection
    raise err
  File "/usr/lib/python3.6/socket.py", line 713, in create_connection
    sock.connect(sa)
ConnectionRefusedError: [Errno 111] Connection refused

During handling of the above exception, another exception occurred:

Traceback (most recent call last):
  File "./index.py", line 20, in application
    init.mysql.connected(init.config['MYSQL']['host'],init.config['MYSQL']['port'],init.config['MYSQL']['database'],init.config['MYSQL']['user'],init.config['MYSQL']['password'])
  File "../lib/MySQLProvider.py", line 10, in connected
    self.connect = pymysql.connect(host=host,user=user,password=password,db=database,port=int(port))
  File "/usr/local/lib/python3.6/dist-packages/pymysql/__init__.py", line 94, in Connect
    return Connection(*args, **kwargs)
  File "/usr/local/lib/python3.6/dist-packages/pymysql/connections.py", line 325, in __init__
    self.connect()
  File "/usr/local/lib/python3.6/dist-packages/pymysql/connections.py", line 630, in connect
    raise exc
pymysql.err.OperationalError: (2003, "Can't connect to MySQL server on 'db' ([Errno 111] Connection refused)")
[pid: 1|app: 0|req: 4/4] 192.168.10.50 () {46 vars in 894 bytes} [Wed Apr  8 03:12:33 2020] GET /favicon.ico => generated 0 bytes in 4 msecs (HTTP/1.1 500) 0 headers in 0 bytes (0 switches on core 0)
*** Starting uWSGI 2.0.18 (64bit) on [Wed Apr  8 03:13:45 2020] ***
compiled with version: 7.5.0 on 07 April 2020 23:31:59
os: Linux-5.0.0-38-generic #41-Ubuntu SMP Tue Dec 3 00:27:35 UTC 2019
nodename: 818033d7d797
machine: x86_64
clock source: unix
detected number of CPU cores: 12
current working directory: /nb/webroot
detected binary path: /usr/local/bin/uwsgi
!!! no internal routing support, rebuild with pcre support !!!
uWSGI running as root, you can use --uid/--gid/--chroot options
*** WARNING: you are running uWSGI as root !!! (use the --uid flag) *** 
*** WARNING: you are running uWSGI without its master process manager ***
your memory page size is 4096 bytes
detected max file descriptor number: 1048576
lock engine: pthread robust mutexes
thunder lock: disabled (you can enable it with --thunder-lock)
uwsgi socket 0 bound to TCP address 0.0.0.0:9201 fd 3
uWSGI running as root, you can use --uid/--gid/--chroot options
*** WARNING: you are running uWSGI as root !!! (use the --uid flag) *** 
Python version: 3.6.9 (default, Nov  7 2019, 10:44:02)  [GCC 8.3.0]
*** Python threads support is disabled. You can enable it with --enable-threads ***
Python main interpreter initialized at 0x559986fca240
uWSGI running as root, you can use --uid/--gid/--chroot options
*** WARNING: you are running uWSGI as root !!! (use the --uid flag) *** 
your server socket listen backlog is limited to 100 connections
your mercy for graceful operations on workers is 60 seconds
mapped 72904 bytes (71 KB) for 1 cores
*** Operational MODE: single process ***
WSGI app 0 (mountpoint='') ready in 0 seconds on interpreter 0x559986fca240 pid: 1 (default app)
uWSGI running as root, you can use --uid/--gid/--chroot options
*** WARNING: you are running uWSGI as root !!! (use the --uid flag) *** 
*** uWSGI is running in multiple interpreter mode ***
spawned uWSGI worker 1 (and the only) (pid: 1, cores: 1)
[pid: 1|app: 0|req: 1/1] 192.168.10.50 () {46 vars in 991 bytes} [Wed Apr  8 03:13:51 2020] GET / => generated 3966 bytes in 107 msecs (HTTP/1.1 200) 1 headers in 44 bytes (1 switches on core 0)
[pid: 1|app: 0|req: 2/2] 192.168.10.50 () {46 vars in 894 bytes} [Wed Apr  8 03:13:51 2020] GET /favicon.ico => generated 2154 bytes in 7 msecs (HTTP/1.1 200) 1 headers in 44 bytes (1 switches on core 0)
*** Starting uWSGI 2.0.18 (64bit) on [Wed Apr  8 03:16:33 2020] ***
compiled with version: 7.5.0 on 07 April 2020 23:31:59
os: Linux-5.0.0-38-generic #41-Ubuntu SMP Tue Dec 3 00:27:35 UTC 2019
nodename: bcd52ff4f348
machine: x86_64
clock source: unix
detected number of CPU cores: 12
current working directory: /nb/webroot
detected binary path: /usr/local/bin/uwsgi
!!! no internal routing support, rebuild with pcre support !!!
uWSGI running as root, you can use --uid/--gid/--chroot options
*** WARNING: you are running uWSGI as root !!! (use the --uid flag) *** 
*** WARNING: you are running uWSGI without its master process manager ***
your memory page size is 4096 bytes
detected max file descriptor number: 1048576
lock engine: pthread robust mutexes
thunder lock: disabled (you can enable it with --thunder-lock)
uwsgi socket 0 bound to TCP address 0.0.0.0:9201 fd 3
uWSGI running as root, you can use --uid/--gid/--chroot options
*** WARNING: you are running uWSGI as root !!! (use the --uid flag) *** 
Python version: 3.6.9 (default, Nov  7 2019, 10:44:02)  [GCC 8.3.0]
*** Python threads support is disabled. You can enable it with --enable-threads ***
Python main interpreter initialized at 0x5616b7a79240
uWSGI running as root, you can use --uid/--gid/--chroot options
*** WARNING: you are running uWSGI as root !!! (use the --uid flag) *** 
your server socket listen backlog is limited to 100 connections
your mercy for graceful operations on workers is 60 seconds
mapped 72904 bytes (71 KB) for 1 cores
*** Operational MODE: single process ***
WSGI app 0 (mountpoint='') ready in 1 seconds on interpreter 0x5616b7a79240 pid: 1 (default app)
uWSGI running as root, you can use --uid/--gid/--chroot options
*** WARNING: you are running uWSGI as root !!! (use the --uid flag) *** 
*** uWSGI is running in multiple interpreter mode ***
spawned uWSGI worker 1 (and the only) (pid: 1, cores: 1)
Traceback (most recent call last):
  File "/usr/local/lib/python3.6/dist-packages/pymysql/connections.py", line 583, in connect
    **kwargs)
  File "/usr/lib/python3.6/socket.py", line 724, in create_connection
    raise err
  File "/usr/lib/python3.6/socket.py", line 713, in create_connection
    sock.connect(sa)
ConnectionRefusedError: [Errno 111] Connection refused

During handling of the above exception, another exception occurred:

Traceback (most recent call last):
  File "./index.py", line 20, in application
    init.mysql.connected(init.config['MYSQL']['host'],init.config['MYSQL']['port'],init.config['MYSQL']['database'],init.config['MYSQL']['user'],init.config['MYSQL']['password'])
  File "../lib/MySQLProvider.py", line 10, in connected
    self.connect = pymysql.connect(host=host,user=user,password=password,db=database,port=int(port))
  File "/usr/local/lib/python3.6/dist-packages/pymysql/__init__.py", line 94, in Connect
    return Connection(*args, **kwargs)
  File "/usr/local/lib/python3.6/dist-packages/pymysql/connections.py", line 325, in __init__
    self.connect()
  File "/usr/local/lib/python3.6/dist-packages/pymysql/connections.py", line 630, in connect
    raise exc
pymysql.err.OperationalError: (2003, "Can't connect to MySQL server on 'db' ([Errno 111] Connection refused)")
[pid: 1|app: 0|req: 1/1] 192.168.10.50 () {46 vars in 991 bytes} [Wed Apr  8 03:16:41 2020] GET / => generated 0 bytes in 9 msecs (HTTP/1.1 500) 0 headers in 0 bytes (0 switches on core 0)
Traceback (most recent call last):
  File "/usr/local/lib/python3.6/dist-packages/pymysql/connections.py", line 583, in connect
    **kwargs)
  File "/usr/lib/python3.6/socket.py", line 724, in create_connection
    raise err
  File "/usr/lib/python3.6/socket.py", line 713, in create_connection
    sock.connect(sa)
ConnectionRefusedError: [Errno 111] Connection refused

During handling of the above exception, another exception occurred:

Traceback (most recent call last):
  File "./index.py", line 20, in application
    init.mysql.connected(init.config['MYSQL']['host'],init.config['MYSQL']['port'],init.config['MYSQL']['database'],init.config['MYSQL']['user'],init.config['MYSQL']['password'])
  File "../lib/MySQLProvider.py", line 10, in connected
    self.connect = pymysql.connect(host=host,user=user,password=password,db=database,port=int(port))
  File "/usr/local/lib/python3.6/dist-packages/pymysql/__init__.py", line 94, in Connect
    return Connection(*args, **kwargs)
  File "/usr/local/lib/python3.6/dist-packages/pymysql/connections.py", line 325, in __init__
    self.connect()
  File "/usr/local/lib/python3.6/dist-packages/pymysql/connections.py", line 630, in connect
    raise exc
pymysql.err.OperationalError: (2003, "Can't connect to MySQL server on 'db' ([Errno 111] Connection refused)")
[pid: 1|app: 0|req: 2/2] 192.168.10.50 () {46 vars in 894 bytes} [Wed Apr  8 03:16:41 2020] GET /favicon.ico => generated 0 bytes in 4 msecs (HTTP/1.1 500) 0 headers in 0 bytes (0 switches on core 0)
Traceback (most recent call last):
  File "/usr/local/lib/python3.6/dist-packages/pymysql/connections.py", line 583, in connect
    **kwargs)
  File "/usr/lib/python3.6/socket.py", line 724, in create_connection
    raise err
  File "/usr/lib/python3.6/socket.py", line 713, in create_connection
    sock.connect(sa)
ConnectionRefusedError: [Errno 111] Connection refused

During handling of the above exception, another exception occurred:

Traceback (most recent call last):
  File "./index.py", line 20, in application
    init.mysql.connected(init.config['MYSQL']['host'],init.config['MYSQL']['port'],init.config['MYSQL']['database'],init.config['MYSQL']['user'],init.config['MYSQL']['password'])
  File "../lib/MySQLProvider.py", line 10, in connected
    self.connect = pymysql.connect(host=host,user=user,password=password,db=database,port=int(port))
  File "/usr/local/lib/python3.6/dist-packages/pymysql/__init__.py", line 94, in Connect
    return Connection(*args, **kwargs)
  File "/usr/local/lib/python3.6/dist-packages/pymysql/connections.py", line 325, in __init__
    self.connect()
  File "/usr/local/lib/python3.6/dist-packages/pymysql/connections.py", line 630, in connect
    raise exc
pymysql.err.OperationalError: (2003, "Can't connect to MySQL server on 'db' ([Errno 111] Connection refused)")
[pid: 1|app: 0|req: 3/3] 192.168.10.50 () {46 vars in 991 bytes} [Wed Apr  8 03:16:42 2020] GET / => generated 0 bytes in 4 msecs (HTTP/1.1 500) 0 headers in 0 bytes (0 switches on core 0)
Traceback (most recent call last):
  File "/usr/local/lib/python3.6/dist-packages/pymysql/connections.py", line 583, in connect
    **kwargs)
  File "/usr/lib/python3.6/socket.py", line 724, in create_connection
    raise err
  File "/usr/lib/python3.6/socket.py", line 713, in create_connection
    sock.connect(sa)
ConnectionRefusedError: [Errno 111] Connection refused

During handling of the above exception, another exception occurred:

Traceback (most recent call last):
  File "./index.py", line 20, in application
    init.mysql.connected(init.config['MYSQL']['host'],init.config['MYSQL']['port'],init.config['MYSQL']['database'],init.config['MYSQL']['user'],init.config['MYSQL']['password'])
  File "../lib/MySQLProvider.py", line 10, in connected
    self.connect = pymysql.connect(host=host,user=user,password=password,db=database,port=int(port))
  File "/usr/local/lib/python3.6/dist-packages/pymysql/__init__.py", line 94, in Connect
    return Connection(*args, **kwargs)
  File "/usr/local/lib/python3.6/dist-packages/pymysql/connections.py", line 325, in __init__
    self.connect()
  File "/usr/local/lib/python3.6/dist-packages/pymysql/connections.py", line 630, in connect
    raise exc
pymysql.err.OperationalError: (2003, "Can't connect to MySQL server on 'db' ([Errno 111] Connection refused)")
[pid: 1|app: 0|req: 4/4] 192.168.10.50 () {46 vars in 894 bytes} [Wed Apr  8 03:16:42 2020] GET /favicon.ico => generated 0 bytes in 2 msecs (HTTP/1.1 500) 0 headers in 0 bytes (0 switches on core 0)
Traceback (most recent call last):
  File "/usr/local/lib/python3.6/dist-packages/pymysql/connections.py", line 583, in connect
    **kwargs)
  File "/usr/lib/python3.6/socket.py", line 724, in create_connection
    raise err
  File "/usr/lib/python3.6/socket.py", line 713, in create_connection
    sock.connect(sa)
ConnectionRefusedError: [Errno 111] Connection refused

During handling of the above exception, another exception occurred:

Traceback (most recent call last):
  File "./index.py", line 20, in application
    init.mysql.connected(init.config['MYSQL']['host'],init.config['MYSQL']['port'],init.config['MYSQL']['database'],init.config['MYSQL']['user'],init.config['MYSQL']['password'])
  File "../lib/MySQLProvider.py", line 10, in connected
    self.connect = pymysql.connect(host=host,user=user,password=password,db=database,port=int(port))
  File "/usr/local/lib/python3.6/dist-packages/pymysql/__init__.py", line 94, in Connect
    return Connection(*args, **kwargs)
  File "/usr/local/lib/python3.6/dist-packages/pymysql/connections.py", line 325, in __init__
    self.connect()
  File "/usr/local/lib/python3.6/dist-packages/pymysql/connections.py", line 630, in connect
    raise exc
pymysql.err.OperationalError: (2003, "Can't connect to MySQL server on 'db' ([Errno 111] Connection refused)")
[pid: 1|app: 0|req: 5/5] 192.168.10.50 () {46 vars in 991 bytes} [Wed Apr  8 03:16:42 2020] GET / => generated 0 bytes in 4 msecs (HTTP/1.1 500) 0 headers in 0 bytes (0 switches on core 0)
Traceback (most recent call last):
  File "/usr/local/lib/python3.6/dist-packages/pymysql/connections.py", line 583, in connect
    **kwargs)
  File "/usr/lib/python3.6/socket.py", line 724, in create_connection
    raise err
  File "/usr/lib/python3.6/socket.py", line 713, in create_connection
    sock.connect(sa)
ConnectionRefusedError: [Errno 111] Connection refused

During handling of the above exception, another exception occurred:

Traceback (most recent call last):
  File "./index.py", line 20, in application
    init.mysql.connected(init.config['MYSQL']['host'],init.config['MYSQL']['port'],init.config['MYSQL']['database'],init.config['MYSQL']['user'],init.config['MYSQL']['password'])
  File "../lib/MySQLProvider.py", line 10, in connected
    self.connect = pymysql.connect(host=host,user=user,password=password,db=database,port=int(port))
  File "/usr/local/lib/python3.6/dist-packages/pymysql/__init__.py", line 94, in Connect
    return Connection(*args, **kwargs)
  File "/usr/local/lib/python3.6/dist-packages/pymysql/connections.py", line 325, in __init__
    self.connect()
  File "/usr/local/lib/python3.6/dist-packages/pymysql/connections.py", line 630, in connect
    raise exc
pymysql.err.OperationalError: (2003, "Can't connect to MySQL server on 'db' ([Errno 111] Connection refused)")
[pid: 1|app: 0|req: 6/6] 192.168.10.50 () {46 vars in 894 bytes} [Wed Apr  8 03:16:42 2020] GET /favicon.ico => generated 0 bytes in 3 msecs (HTTP/1.1 500) 0 headers in 0 bytes (0 switches on core 0)
Traceback (most recent call last):
  File "/usr/local/lib/python3.6/dist-packages/pymysql/connections.py", line 583, in connect
    **kwargs)
  File "/usr/lib/python3.6/socket.py", line 724, in create_connection
    raise err
  File "/usr/lib/python3.6/socket.py", line 713, in create_connection
    sock.connect(sa)
ConnectionRefusedError: [Errno 111] Connection refused

During handling of the above exception, another exception occurred:

Traceback (most recent call last):
  File "./index.py", line 20, in application
    init.mysql.connected(init.config['MYSQL']['host'],init.config['MYSQL']['port'],init.config['MYSQL']['database'],init.config['MYSQL']['user'],init.config['MYSQL']['password'])
  File "../lib/MySQLProvider.py", line 10, in connected
    self.connect = pymysql.connect(host=host,user=user,password=password,db=database,port=int(port))
  File "/usr/local/lib/python3.6/dist-packages/pymysql/__init__.py", line 94, in Connect
    return Connection(*args, **kwargs)
  File "/usr/local/lib/python3.6/dist-packages/pymysql/connections.py", line 325, in __init__
    self.connect()
  File "/usr/local/lib/python3.6/dist-packages/pymysql/connections.py", line 630, in connect
    raise exc
pymysql.err.OperationalError: (2003, "Can't connect to MySQL server on 'db' ([Errno 111] Connection refused)")
[pid: 1|app: 0|req: 7/7] 192.168.10.50 () {46 vars in 991 bytes} [Wed Apr  8 03:16:49 2020] GET / => generated 0 bytes in 4 msecs (HTTP/1.1 500) 0 headers in 0 bytes (0 switches on core 0)
Traceback (most recent call last):
  File "/usr/local/lib/python3.6/dist-packages/pymysql/connections.py", line 583, in connect
    **kwargs)
  File "/usr/lib/python3.6/socket.py", line 724, in create_connection
    raise err
  File "/usr/lib/python3.6/socket.py", line 713, in create_connection
    sock.connect(sa)
ConnectionRefusedError: [Errno 111] Connection refused

During handling of the above exception, another exception occurred:

Traceback (most recent call last):
  File "./index.py", line 20, in application
    init.mysql.connected(init.config['MYSQL']['host'],init.config['MYSQL']['port'],init.config['MYSQL']['database'],init.config['MYSQL']['user'],init.config['MYSQL']['password'])
  File "../lib/MySQLProvider.py", line 10, in connected
    self.connect = pymysql.connect(host=host,user=user,password=password,db=database,port=int(port))
  File "/usr/local/lib/python3.6/dist-packages/pymysql/__init__.py", line 94, in Connect
    return Connection(*args, **kwargs)
  File "/usr/local/lib/python3.6/dist-packages/pymysql/connections.py", line 325, in __init__
    self.connect()
  File "/usr/local/lib/python3.6/dist-packages/pymysql/connections.py", line 630, in connect
    raise exc
pymysql.err.OperationalError: (2003, "Can't connect to MySQL server on 'db' ([Errno 111] Connection refused)")
[pid: 1|app: 0|req: 8/8] 192.168.10.50 () {46 vars in 894 bytes} [Wed Apr  8 03:16:49 2020] GET /favicon.ico => generated 0 bytes in 3 msecs (HTTP/1.1 500) 0 headers in 0 bytes (0 switches on core 0)
Traceback (most recent call last):
  File "/usr/local/lib/python3.6/dist-packages/pymysql/connections.py", line 583, in connect
    **kwargs)
  File "/usr/lib/python3.6/socket.py", line 724, in create_connection
    raise err
  File "/usr/lib/python3.6/socket.py", line 713, in create_connection
    sock.connect(sa)
ConnectionRefusedError: [Errno 111] Connection refused

During handling of the above exception, another exception occurred:

Traceback (most recent call last):
  File "./index.py", line 20, in application
    init.mysql.connected(init.config['MYSQL']['host'],init.config['MYSQL']['port'],init.config['MYSQL']['database'],init.config['MYSQL']['user'],init.config['MYSQL']['password'])
  File "../lib/MySQLProvider.py", line 10, in connected
    self.connect = pymysql.connect(host=host,user=user,password=password,db=database,port=int(port))
  File "/usr/local/lib/python3.6/dist-packages/pymysql/__init__.py", line 94, in Connect
    return Connection(*args, **kwargs)
  File "/usr/local/lib/python3.6/dist-packages/pymysql/connections.py", line 325, in __init__
    self.connect()
  File "/usr/local/lib/python3.6/dist-packages/pymysql/connections.py", line 630, in connect
    raise exc
pymysql.err.OperationalError: (2003, "Can't connect to MySQL server on 'db' ([Errno 111] Connection refused)")
[pid: 1|app: 0|req: 9/9] 192.168.10.50 () {46 vars in 991 bytes} [Wed Apr  8 03:16:50 2020] GET / => generated 0 bytes in 5 msecs (HTTP/1.1 500) 0 headers in 0 bytes (0 switches on core 0)
Traceback (most recent call last):
  File "/usr/local/lib/python3.6/dist-packages/pymysql/connections.py", line 583, in connect
    **kwargs)
  File "/usr/lib/python3.6/socket.py", line 724, in create_connection
    raise err
  File "/usr/lib/python3.6/socket.py", line 713, in create_connection
    sock.connect(sa)
ConnectionRefusedError: [Errno 111] Connection refused

During handling of the above exception, another exception occurred:

Traceback (most recent call last):
  File "./index.py", line 20, in application
    init.mysql.connected(init.config['MYSQL']['host'],init.config['MYSQL']['port'],init.config['MYSQL']['database'],init.config['MYSQL']['user'],init.config['MYSQL']['password'])
  File "../lib/MySQLProvider.py", line 10, in connected
    self.connect = pymysql.connect(host=host,user=user,password=password,db=database,port=int(port))
  File "/usr/local/lib/python3.6/dist-packages/pymysql/__init__.py", line 94, in Connect
    return Connection(*args, **kwargs)
  File "/usr/local/lib/python3.6/dist-packages/pymysql/connections.py", line 325, in __init__
    self.connect()
  File "/usr/local/lib/python3.6/dist-packages/pymysql/connections.py", line 630, in connect
    raise exc
pymysql.err.OperationalError: (2003, "Can't connect to MySQL server on 'db' ([Errno 111] Connection refused)")
[pid: 1|app: 0|req: 10/10] 192.168.10.50 () {46 vars in 894 bytes} [Wed Apr  8 03:16:50 2020] GET /favicon.ico => generated 0 bytes in 4 msecs (HTTP/1.1 500) 0 headers in 0 bytes (0 switches on core 0)
Traceback (most recent call last):
  File "/usr/local/lib/python3.6/dist-packages/pymysql/connections.py", line 583, in connect
    **kwargs)
  File "/usr/lib/python3.6/socket.py", line 724, in create_connection
    raise err
  File "/usr/lib/python3.6/socket.py", line 713, in create_connection
    sock.connect(sa)
ConnectionRefusedError: [Errno 111] Connection refused

During handling of the above exception, another exception occurred:

Traceback (most recent call last):
  File "./index.py", line 20, in application
    init.mysql.connected(init.config['MYSQL']['host'],init.config['MYSQL']['port'],init.config['MYSQL']['database'],init.config['MYSQL']['user'],init.config['MYSQL']['password'])
  File "../lib/MySQLProvider.py", line 10, in connected
    self.connect = pymysql.connect(host=host,user=user,password=password,db=database,port=int(port))
  File "/usr/local/lib/python3.6/dist-packages/pymysql/__init__.py", line 94, in Connect
    return Connection(*args, **kwargs)
  File "/usr/local/lib/python3.6/dist-packages/pymysql/connections.py", line 325, in __init__
    self.connect()
  File "/usr/local/lib/python3.6/dist-packages/pymysql/connections.py", line 630, in connect
    raise exc
pymysql.err.OperationalError: (2003, "Can't connect to MySQL server on 'db' ([Errno 111] Connection refused)")
[pid: 1|app: 0|req: 11/11] 192.168.10.50 () {46 vars in 991 bytes} [Wed Apr  8 03:16:50 2020] GET / => generated 0 bytes in 2 msecs (HTTP/1.1 500) 0 headers in 0 bytes (0 switches on core 0)
Traceback (most recent call last):
  File "/usr/local/lib/python3.6/dist-packages/pymysql/connections.py", line 583, in connect
    **kwargs)
  File "/usr/lib/python3.6/socket.py", line 724, in create_connection
    raise err
  File "/usr/lib/python3.6/socket.py", line 713, in create_connection
    sock.connect(sa)
ConnectionRefusedError: [Errno 111] Connection refused

During handling of the above exception, another exception occurred:

Traceback (most recent call last):
  File "./index.py", line 20, in application
    init.mysql.connected(init.config['MYSQL']['host'],init.config['MYSQL']['port'],init.config['MYSQL']['database'],init.config['MYSQL']['user'],init.config['MYSQL']['password'])
  File "../lib/MySQLProvider.py", line 10, in connected
    self.connect = pymysql.connect(host=host,user=user,password=password,db=database,port=int(port))
  File "/usr/local/lib/python3.6/dist-packages/pymysql/__init__.py", line 94, in Connect
    return Connection(*args, **kwargs)
  File "/usr/local/lib/python3.6/dist-packages/pymysql/connections.py", line 325, in __init__
    self.connect()
  File "/usr/local/lib/python3.6/dist-packages/pymysql/connections.py", line 630, in connect
    raise exc
pymysql.err.OperationalError: (2003, "Can't connect to MySQL server on 'db' ([Errno 111] Connection refused)")
[pid: 1|app: 0|req: 12/12] 192.168.10.50 () {46 vars in 894 bytes} [Wed Apr  8 03:16:50 2020] GET /favicon.ico => generated 0 bytes in 1 msecs (HTTP/1.1 500) 0 headers in 0 bytes (0 switches on core 0)
Traceback (most recent call last):
  File "/usr/local/lib/python3.6/dist-packages/pymysql/connections.py", line 583, in connect
    **kwargs)
  File "/usr/lib/python3.6/socket.py", line 724, in create_connection
    raise err
  File "/usr/lib/python3.6/socket.py", line 713, in create_connection
    sock.connect(sa)
ConnectionRefusedError: [Errno 111] Connection refused

During handling of the above exception, another exception occurred:

Traceback (most recent call last):
  File "./index.py", line 20, in application
    init.mysql.connected(init.config['MYSQL']['host'],init.config['MYSQL']['port'],init.config['MYSQL']['database'],init.config['MYSQL']['user'],init.config['MYSQL']['password'])
  File "../lib/MySQLProvider.py", line 10, in connected
    self.connect = pymysql.connect(host=host,user=user,password=password,db=database,port=int(port))
  File "/usr/local/lib/python3.6/dist-packages/pymysql/__init__.py", line 94, in Connect
    return Connection(*args, **kwargs)
  File "/usr/local/lib/python3.6/dist-packages/pymysql/connections.py", line 325, in __init__
    self.connect()
  File "/usr/local/lib/python3.6/dist-packages/pymysql/connections.py", line 630, in connect
    raise exc
pymysql.err.OperationalError: (2003, "Can't connect to MySQL server on 'db' ([Errno 111] Connection refused)")
[pid: 1|app: 0|req: 13/13] 192.168.10.50 () {46 vars in 991 bytes} [Wed Apr  8 03:16:59 2020] GET / => generated 0 bytes in 2 msecs (HTTP/1.1 500) 0 headers in 0 bytes (0 switches on core 0)
Traceback (most recent call last):
  File "/usr/local/lib/python3.6/dist-packages/pymysql/connections.py", line 583, in connect
    **kwargs)
  File "/usr/lib/python3.6/socket.py", line 724, in create_connection
    raise err
  File "/usr/lib/python3.6/socket.py", line 713, in create_connection
    sock.connect(sa)
ConnectionRefusedError: [Errno 111] Connection refused

During handling of the above exception, another exception occurred:

Traceback (most recent call last):
  File "./index.py", line 20, in application
    init.mysql.connected(init.config['MYSQL']['host'],init.config['MYSQL']['port'],init.config['MYSQL']['database'],init.config['MYSQL']['user'],init.config['MYSQL']['password'])
  File "../lib/MySQLProvider.py", line 10, in connected
    self.connect = pymysql.connect(host=host,user=user,password=password,db=database,port=int(port))
  File "/usr/local/lib/python3.6/dist-packages/pymysql/__init__.py", line 94, in Connect
    return Connection(*args, **kwargs)
  File "/usr/local/lib/python3.6/dist-packages/pymysql/connections.py", line 325, in __init__
    self.connect()
  File "/usr/local/lib/python3.6/dist-packages/pymysql/connections.py", line 630, in connect
    raise exc
pymysql.err.OperationalError: (2003, "Can't connect to MySQL server on 'db' ([Errno 111] Connection refused)")
[pid: 1|app: 0|req: 14/14] 192.168.10.50 () {46 vars in 894 bytes} [Wed Apr  8 03:16:59 2020] GET /favicon.ico => generated 0 bytes in 1 msecs (HTTP/1.1 500) 0 headers in 0 bytes (0 switches on core 0)
Traceback (most recent call last):
  File "/usr/local/lib/python3.6/dist-packages/pymysql/connections.py", line 583, in connect
    **kwargs)
  File "/usr/lib/python3.6/socket.py", line 724, in create_connection
    raise err
  File "/usr/lib/python3.6/socket.py", line 713, in create_connection
    sock.connect(sa)
ConnectionRefusedError: [Errno 111] Connection refused

During handling of the above exception, another exception occurred:

Traceback (most recent call last):
  File "./index.py", line 20, in application
    init.mysql.connected(init.config['MYSQL']['host'],init.config['MYSQL']['port'],init.config['MYSQL']['database'],init.config['MYSQL']['user'],init.config['MYSQL']['password'])
  File "../lib/MySQLProvider.py", line 10, in connected
    self.connect = pymysql.connect(host=host,user=user,password=password,db=database,port=int(port))
  File "/usr/local/lib/python3.6/dist-packages/pymysql/__init__.py", line 94, in Connect
    return Connection(*args, **kwargs)
  File "/usr/local/lib/python3.6/dist-packages/pymysql/connections.py", line 325, in __init__
    self.connect()
  File "/usr/local/lib/python3.6/dist-packages/pymysql/connections.py", line 630, in connect
    raise exc
pymysql.err.OperationalError: (2003, "Can't connect to MySQL server on 'db' ([Errno 111] Connection refused)")
[pid: 1|app: 0|req: 15/15] 192.168.10.50 () {46 vars in 991 bytes} [Wed Apr  8 03:17:01 2020] GET / => generated 0 bytes in 4 msecs (HTTP/1.1 500) 0 headers in 0 bytes (0 switches on core 0)
Traceback (most recent call last):
  File "/usr/local/lib/python3.6/dist-packages/pymysql/connections.py", line 583, in connect
    **kwargs)
  File "/usr/lib/python3.6/socket.py", line 724, in create_connection
    raise err
  File "/usr/lib/python3.6/socket.py", line 713, in create_connection
    sock.connect(sa)
ConnectionRefusedError: [Errno 111] Connection refused

During handling of the above exception, another exception occurred:

Traceback (most recent call last):
  File "./index.py", line 20, in application
    init.mysql.connected(init.config['MYSQL']['host'],init.config['MYSQL']['port'],init.config['MYSQL']['database'],init.config['MYSQL']['user'],init.config['MYSQL']['password'])
  File "../lib/MySQLProvider.py", line 10, in connected
    self.connect = pymysql.connect(host=host,user=user,password=password,db=database,port=int(port))
  File "/usr/local/lib/python3.6/dist-packages/pymysql/__init__.py", line 94, in Connect
    return Connection(*args, **kwargs)
  File "/usr/local/lib/python3.6/dist-packages/pymysql/connections.py", line 325, in __init__
    self.connect()
  File "/usr/local/lib/python3.6/dist-packages/pymysql/connections.py", line 630, in connect
    raise exc
pymysql.err.OperationalError: (2003, "Can't connect to MySQL server on 'db' ([Errno 111] Connection refused)")
[pid: 1|app: 0|req: 16/16] 192.168.10.50 () {46 vars in 894 bytes} [Wed Apr  8 03:17:01 2020] GET /favicon.ico => generated 0 bytes in 2 msecs (HTTP/1.1 500) 0 headers in 0 bytes (0 switches on core 0)
Traceback (most recent call last):
  File "/usr/local/lib/python3.6/dist-packages/pymysql/connections.py", line 583, in connect
    **kwargs)
  File "/usr/lib/python3.6/socket.py", line 724, in create_connection
    raise err
  File "/usr/lib/python3.6/socket.py", line 713, in create_connection
    sock.connect(sa)
ConnectionRefusedError: [Errno 111] Connection refused

During handling of the above exception, another exception occurred:

Traceback (most recent call last):
  File "./index.py", line 20, in application
    init.mysql.connected(init.config['MYSQL']['host'],init.config['MYSQL']['port'],init.config['MYSQL']['database'],init.config['MYSQL']['user'],init.config['MYSQL']['password'])
  File "../lib/MySQLProvider.py", line 10, in connected
    self.connect = pymysql.connect(host=host,user=user,password=password,db=database,port=int(port))
  File "/usr/local/lib/python3.6/dist-packages/pymysql/__init__.py", line 94, in Connect
    return Connection(*args, **kwargs)
  File "/usr/local/lib/python3.6/dist-packages/pymysql/connections.py", line 325, in __init__
    self.connect()
  File "/usr/local/lib/python3.6/dist-packages/pymysql/connections.py", line 630, in connect
    raise exc
pymysql.err.OperationalError: (2003, "Can't connect to MySQL server on 'db' ([Errno 111] Connection refused)")
[pid: 1|app: 0|req: 17/17] 192.168.10.50 () {46 vars in 991 bytes} [Wed Apr  8 03:17:02 2020] GET / => generated 0 bytes in 2 msecs (HTTP/1.1 500) 0 headers in 0 bytes (0 switches on core 0)
Traceback (most recent call last):
  File "/usr/local/lib/python3.6/dist-packages/pymysql/connections.py", line 583, in connect
    **kwargs)
  File "/usr/lib/python3.6/socket.py", line 724, in create_connection
    raise err
  File "/usr/lib/python3.6/socket.py", line 713, in create_connection
    sock.connect(sa)
ConnectionRefusedError: [Errno 111] Connection refused

During handling of the above exception, another exception occurred:

Traceback (most recent call last):
  File "./index.py", line 20, in application
    init.mysql.connected(init.config['MYSQL']['host'],init.config['MYSQL']['port'],init.config['MYSQL']['database'],init.config['MYSQL']['user'],init.config['MYSQL']['password'])
  File "../lib/MySQLProvider.py", line 10, in connected
    self.connect = pymysql.connect(host=host,user=user,password=password,db=database,port=int(port))
  File "/usr/local/lib/python3.6/dist-packages/pymysql/__init__.py", line 94, in Connect
    return Connection(*args, **kwargs)
  File "/usr/local/lib/python3.6/dist-packages/pymysql/connections.py", line 325, in __init__
    self.connect()
  File "/usr/local/lib/python3.6/dist-packages/pymysql/connections.py", line 630, in connect
    raise exc
pymysql.err.OperationalError: (2003, "Can't connect to MySQL server on 'db' ([Errno 111] Connection refused)")
[pid: 1|app: 0|req: 18/18] 192.168.10.50 () {46 vars in 894 bytes} [Wed Apr  8 03:17:02 2020] GET /favicon.ico => generated 0 bytes in 1 msecs (HTTP/1.1 500) 0 headers in 0 bytes (0 switches on core 0)
Traceback (most recent call last):
  File "/usr/local/lib/python3.6/dist-packages/pymysql/connections.py", line 583, in connect
    **kwargs)
  File "/usr/lib/python3.6/socket.py", line 724, in create_connection
    raise err
  File "/usr/lib/python3.6/socket.py", line 713, in create_connection
    sock.connect(sa)
ConnectionRefusedError: [Errno 111] Connection refused

During handling of the above exception, another exception occurred:

Traceback (most recent call last):
  File "./index.py", line 20, in application
    init.mysql.connected(init.config['MYSQL']['host'],init.config['MYSQL']['port'],init.config['MYSQL']['database'],init.config['MYSQL']['user'],init.config['MYSQL']['password'])
  File "../lib/MySQLProvider.py", line 10, in connected
    self.connect = pymysql.connect(host=host,user=user,password=password,db=database,port=int(port))
  File "/usr/local/lib/python3.6/dist-packages/pymysql/__init__.py", line 94, in Connect
    return Connection(*args, **kwargs)
  File "/usr/local/lib/python3.6/dist-packages/pymysql/connections.py", line 325, in __init__
    self.connect()
  File "/usr/local/lib/python3.6/dist-packages/pymysql/connections.py", line 630, in connect
    raise exc
pymysql.err.OperationalError: (2003, "Can't connect to MySQL server on 'db' ([Errno 111] Connection refused)")
[pid: 1|app: 0|req: 19/19] 192.168.10.50 () {46 vars in 991 bytes} [Wed Apr  8 03:17:02 2020] GET / => generated 0 bytes in 4 msecs (HTTP/1.1 500) 0 headers in 0 bytes (0 switches on core 0)
Traceback (most recent call last):
  File "/usr/local/lib/python3.6/dist-packages/pymysql/connections.py", line 583, in connect
    **kwargs)
  File "/usr/lib/python3.6/socket.py", line 724, in create_connection
    raise err
  File "/usr/lib/python3.6/socket.py", line 713, in create_connection
    sock.connect(sa)
ConnectionRefusedError: [Errno 111] Connection refused

During handling of the above exception, another exception occurred:

Traceback (most recent call last):
  File "./index.py", line 20, in application
    init.mysql.connected(init.config['MYSQL']['host'],init.config['MYSQL']['port'],init.config['MYSQL']['database'],init.config['MYSQL']['user'],init.config['MYSQL']['password'])
  File "../lib/MySQLProvider.py", line 10, in connected
    self.connect = pymysql.connect(host=host,user=user,password=password,db=database,port=int(port))
  File "/usr/local/lib/python3.6/dist-packages/pymysql/__init__.py", line 94, in Connect
    return Connection(*args, **kwargs)
  File "/usr/local/lib/python3.6/dist-packages/pymysql/connections.py", line 325, in __init__
    self.connect()
  File "/usr/local/lib/python3.6/dist-packages/pymysql/connections.py", line 630, in connect
    raise exc
pymysql.err.OperationalError: (2003, "Can't connect to MySQL server on 'db' ([Errno 111] Connection refused)")
[pid: 1|app: 0|req: 20/20] 192.168.10.50 () {46 vars in 894 bytes} [Wed Apr  8 03:17:02 2020] GET /favicon.ico => generated 0 bytes in 3 msecs (HTTP/1.1 500) 0 headers in 0 bytes (0 switches on core 0)
Traceback (most recent call last):
  File "/usr/local/lib/python3.6/dist-packages/pymysql/connections.py", line 583, in connect
    **kwargs)
  File "/usr/lib/python3.6/socket.py", line 724, in create_connection
    raise err
  File "/usr/lib/python3.6/socket.py", line 713, in create_connection
    sock.connect(sa)
ConnectionRefusedError: [Errno 111] Connection refused

During handling of the above exception, another exception occurred:

Traceback (most recent call last):
  File "./index.py", line 20, in application
    init.mysql.connected(init.config['MYSQL']['host'],init.config['MYSQL']['port'],init.config['MYSQL']['database'],init.config['MYSQL']['user'],init.config['MYSQL']['password'])
  File "../lib/MySQLProvider.py", line 10, in connected
    self.connect = pymysql.connect(host=host,user=user,password=password,db=database,port=int(port))
  File "/usr/local/lib/python3.6/dist-packages/pymysql/__init__.py", line 94, in Connect
    return Connection(*args, **kwargs)
  File "/usr/local/lib/python3.6/dist-packages/pymysql/connections.py", line 325, in __init__
    self.connect()
  File "/usr/local/lib/python3.6/dist-packages/pymysql/connections.py", line 630, in connect
    raise exc
pymysql.err.OperationalError: (2003, "Can't connect to MySQL server on 'db' ([Errno 111] Connection refused)")
[pid: 1|app: 0|req: 21/21] 192.168.10.50 () {46 vars in 991 bytes} [Wed Apr  8 03:17:02 2020] GET / => generated 0 bytes in 2 msecs (HTTP/1.1 500) 0 headers in 0 bytes (0 switches on core 0)
Traceback (most recent call last):
  File "/usr/local/lib/python3.6/dist-packages/pymysql/connections.py", line 583, in connect
    **kwargs)
  File "/usr/lib/python3.6/socket.py", line 724, in create_connection
    raise err
  File "/usr/lib/python3.6/socket.py", line 713, in create_connection
    sock.connect(sa)
ConnectionRefusedError: [Errno 111] Connection refused

During handling of the above exception, another exception occurred:

Traceback (most recent call last):
  File "./index.py", line 20, in application
    init.mysql.connected(init.config['MYSQL']['host'],init.config['MYSQL']['port'],init.config['MYSQL']['database'],init.config['MYSQL']['user'],init.config['MYSQL']['password'])
  File "../lib/MySQLProvider.py", line 10, in connected
    self.connect = pymysql.connect(host=host,user=user,password=password,db=database,port=int(port))
  File "/usr/local/lib/python3.6/dist-packages/pymysql/__init__.py", line 94, in Connect
    return Connection(*args, **kwargs)
  File "/usr/local/lib/python3.6/dist-packages/pymysql/connections.py", line 325, in __init__
    self.connect()
  File "/usr/local/lib/python3.6/dist-packages/pymysql/connections.py", line 630, in connect
    raise exc
pymysql.err.OperationalError: (2003, "Can't connect to MySQL server on 'db' ([Errno 111] Connection refused)")
[pid: 1|app: 0|req: 22/22] 192.168.10.50 () {46 vars in 894 bytes} [Wed Apr  8 03:17:02 2020] GET /favicon.ico => generated 0 bytes in 4 msecs (HTTP/1.1 500) 0 headers in 0 bytes (0 switches on core 0)
Traceback (most recent call last):
  File "/usr/local/lib/python3.6/dist-packages/pymysql/connections.py", line 583, in connect
    **kwargs)
  File "/usr/lib/python3.6/socket.py", line 724, in create_connection
    raise err
  File "/usr/lib/python3.6/socket.py", line 713, in create_connection
    sock.connect(sa)
ConnectionRefusedError: [Errno 111] Connection refused

During handling of the above exception, another exception occurred:

Traceback (most recent call last):
  File "./index.py", line 20, in application
    init.mysql.connected(init.config['MYSQL']['host'],init.config['MYSQL']['port'],init.config['MYSQL']['database'],init.config['MYSQL']['user'],init.config['MYSQL']['password'])
  File "../lib/MySQLProvider.py", line 10, in connected
    self.connect = pymysql.connect(host=host,user=user,password=password,db=database,port=int(port))
  File "/usr/local/lib/python3.6/dist-packages/pymysql/__init__.py", line 94, in Connect
    return Connection(*args, **kwargs)
  File "/usr/local/lib/python3.6/dist-packages/pymysql/connections.py", line 325, in __init__
    self.connect()
  File "/usr/local/lib/python3.6/dist-packages/pymysql/connections.py", line 630, in connect
    raise exc
pymysql.err.OperationalError: (2003, "Can't connect to MySQL server on 'db' ([Errno 111] Connection refused)")
[pid: 1|app: 0|req: 23/23] 192.168.10.50 () {46 vars in 991 bytes} [Wed Apr  8 03:17:03 2020] GET / => generated 0 bytes in 4 msecs (HTTP/1.1 500) 0 headers in 0 bytes (0 switches on core 0)
Traceback (most recent call last):
  File "/usr/local/lib/python3.6/dist-packages/pymysql/connections.py", line 583, in connect
    **kwargs)
  File "/usr/lib/python3.6/socket.py", line 724, in create_connection
    raise err
  File "/usr/lib/python3.6/socket.py", line 713, in create_connection
    sock.connect(sa)
ConnectionRefusedError: [Errno 111] Connection refused

During handling of the above exception, another exception occurred:

Traceback (most recent call last):
  File "./index.py", line 20, in application
    init.mysql.connected(init.config['MYSQL']['host'],init.config['MYSQL']['port'],init.config['MYSQL']['database'],init.config['MYSQL']['user'],init.config['MYSQL']['password'])
  File "../lib/MySQLProvider.py", line 10, in connected
    self.connect = pymysql.connect(host=host,user=user,password=password,db=database,port=int(port))
  File "/usr/local/lib/python3.6/dist-packages/pymysql/__init__.py", line 94, in Connect
    return Connection(*args, **kwargs)
  File "/usr/local/lib/python3.6/dist-packages/pymysql/connections.py", line 325, in __init__
    self.connect()
  File "/usr/local/lib/python3.6/dist-packages/pymysql/connections.py", line 630, in connect
    raise exc
pymysql.err.OperationalError: (2003, "Can't connect to MySQL server on 'db' ([Errno 111] Connection refused)")
[pid: 1|app: 0|req: 24/24] 192.168.10.50 () {46 vars in 894 bytes} [Wed Apr  8 03:17:03 2020] GET /favicon.ico => generated 0 bytes in 3 msecs (HTTP/1.1 500) 0 headers in 0 bytes (0 switches on core 0)
Traceback (most recent call last):
  File "/usr/local/lib/python3.6/dist-packages/pymysql/connections.py", line 583, in connect
    **kwargs)
  File "/usr/lib/python3.6/socket.py", line 724, in create_connection
    raise err
  File "/usr/lib/python3.6/socket.py", line 713, in create_connection
    sock.connect(sa)
ConnectionRefusedError: [Errno 111] Connection refused

During handling of the above exception, another exception occurred:

Traceback (most recent call last):
  File "./index.py", line 20, in application
    init.mysql.connected(init.config['MYSQL']['host'],init.config['MYSQL']['port'],init.config['MYSQL']['database'],init.config['MYSQL']['user'],init.config['MYSQL']['password'])
  File "../lib/MySQLProvider.py", line 10, in connected
    self.connect = pymysql.connect(host=host,user=user,password=password,db=database,port=int(port))
  File "/usr/local/lib/python3.6/dist-packages/pymysql/__init__.py", line 94, in Connect
    return Connection(*args, **kwargs)
  File "/usr/local/lib/python3.6/dist-packages/pymysql/connections.py", line 325, in __init__
    self.connect()
  File "/usr/local/lib/python3.6/dist-packages/pymysql/connections.py", line 630, in connect
    raise exc
pymysql.err.OperationalError: (2003, "Can't connect to MySQL server on 'db' ([Errno 111] Connection refused)")
[pid: 1|app: 0|req: 25/25] 192.168.10.50 () {46 vars in 991 bytes} [Wed Apr  8 03:17:03 2020] GET / => generated 0 bytes in 2 msecs (HTTP/1.1 500) 0 headers in 0 bytes (0 switches on core 0)
Traceback (most recent call last):
  File "/usr/local/lib/python3.6/dist-packages/pymysql/connections.py", line 583, in connect
    **kwargs)
  File "/usr/lib/python3.6/socket.py", line 724, in create_connection
    raise err
  File "/usr/lib/python3.6/socket.py", line 713, in create_connection
    sock.connect(sa)
ConnectionRefusedError: [Errno 111] Connection refused

During handling of the above exception, another exception occurred:

Traceback (most recent call last):
  File "./index.py", line 20, in application
    init.mysql.connected(init.config['MYSQL']['host'],init.config['MYSQL']['port'],init.config['MYSQL']['database'],init.config['MYSQL']['user'],init.config['MYSQL']['password'])
  File "../lib/MySQLProvider.py", line 10, in connected
    self.connect = pymysql.connect(host=host,user=user,password=password,db=database,port=int(port))
  File "/usr/local/lib/python3.6/dist-packages/pymysql/__init__.py", line 94, in Connect
    return Connection(*args, **kwargs)
  File "/usr/local/lib/python3.6/dist-packages/pymysql/connections.py", line 325, in __init__
    self.connect()
  File "/usr/local/lib/python3.6/dist-packages/pymysql/connections.py", line 630, in connect
    raise exc
pymysql.err.OperationalError: (2003, "Can't connect to MySQL server on 'db' ([Errno 111] Connection refused)")
[pid: 1|app: 0|req: 26/26] 192.168.10.50 () {46 vars in 894 bytes} [Wed Apr  8 03:17:03 2020] GET /favicon.ico => generated 0 bytes in 4 msecs (HTTP/1.1 500) 0 headers in 0 bytes (0 switches on core 0)
Traceback (most recent call last):
  File "/usr/local/lib/python3.6/dist-packages/pymysql/connections.py", line 583, in connect
    **kwargs)
  File "/usr/lib/python3.6/socket.py", line 724, in create_connection
    raise err
  File "/usr/lib/python3.6/socket.py", line 713, in create_connection
    sock.connect(sa)
ConnectionRefusedError: [Errno 111] Connection refused

During handling of the above exception, another exception occurred:

Traceback (most recent call last):
  File "./index.py", line 20, in application
    init.mysql.connected(init.config['MYSQL']['host'],init.config['MYSQL']['port'],init.config['MYSQL']['database'],init.config['MYSQL']['user'],init.config['MYSQL']['password'])
  File "../lib/MySQLProvider.py", line 10, in connected
    self.connect = pymysql.connect(host=host,user=user,password=password,db=database,port=int(port))
  File "/usr/local/lib/python3.6/dist-packages/pymysql/__init__.py", line 94, in Connect
    return Connection(*args, **kwargs)
  File "/usr/local/lib/python3.6/dist-packages/pymysql/connections.py", line 325, in __init__
    self.connect()
  File "/usr/local/lib/python3.6/dist-packages/pymysql/connections.py", line 630, in connect
    raise exc
pymysql.err.OperationalError: (2003, "Can't connect to MySQL server on 'db' ([Errno 111] Connection refused)")
[pid: 1|app: 0|req: 27/27] 192.168.10.50 () {46 vars in 991 bytes} [Wed Apr  8 03:17:03 2020] GET / => generated 0 bytes in 4 msecs (HTTP/1.1 500) 0 headers in 0 bytes (0 switches on core 0)
Traceback (most recent call last):
  File "/usr/local/lib/python3.6/dist-packages/pymysql/connections.py", line 583, in connect
    **kwargs)
  File "/usr/lib/python3.6/socket.py", line 724, in create_connection
    raise err
  File "/usr/lib/python3.6/socket.py", line 713, in create_connection
    sock.connect(sa)
ConnectionRefusedError: [Errno 111] Connection refused

During handling of the above exception, another exception occurred:

Traceback (most recent call last):
  File "./index.py", line 20, in application
    init.mysql.connected(init.config['MYSQL']['host'],init.config['MYSQL']['port'],init.config['MYSQL']['database'],init.config['MYSQL']['user'],init.config['MYSQL']['password'])
  File "../lib/MySQLProvider.py", line 10, in connected
    self.connect = pymysql.connect(host=host,user=user,password=password,db=database,port=int(port))
  File "/usr/local/lib/python3.6/dist-packages/pymysql/__init__.py", line 94, in Connect
    return Connection(*args, **kwargs)
  File "/usr/local/lib/python3.6/dist-packages/pymysql/connections.py", line 325, in __init__
    self.connect()
  File "/usr/local/lib/python3.6/dist-packages/pymysql/connections.py", line 630, in connect
    raise exc
pymysql.err.OperationalError: (2003, "Can't connect to MySQL server on 'db' ([Errno 111] Connection refused)")
[pid: 1|app: 0|req: 28/28] 192.168.10.50 () {46 vars in 894 bytes} [Wed Apr  8 03:17:03 2020] GET /favicon.ico => generated 0 bytes in 2 msecs (HTTP/1.1 500) 0 headers in 0 bytes (0 switches on core 0)
[pid: 1|app: 0|req: 29/29] 192.168.10.50 () {46 vars in 991 bytes} [Wed Apr  8 03:17:08 2020] GET / => generated 3407 bytes in 101 msecs (HTTP/1.1 200) 1 headers in 44 bytes (1 switches on core 0)
[pid: 1|app: 0|req: 30/30] 192.168.10.50 () {46 vars in 894 bytes} [Wed Apr  8 03:17:08 2020] GET /favicon.ico => generated 2154 bytes in 7 msecs (HTTP/1.1 200) 1 headers in 44 bytes (1 switches on core 0)
*** Starting uWSGI 2.0.18 (64bit) on [Wed Apr  8 03:18:30 2020] ***
compiled with version: 7.5.0 on 07 April 2020 23:31:59
os: Linux-5.0.0-38-generic #41-Ubuntu SMP Tue Dec 3 00:27:35 UTC 2019
nodename: d3acbcc2b910
machine: x86_64
clock source: unix
detected number of CPU cores: 12
current working directory: /nb/webroot
detected binary path: /usr/local/bin/uwsgi
!!! no internal routing support, rebuild with pcre support !!!
uWSGI running as root, you can use --uid/--gid/--chroot options
*** WARNING: you are running uWSGI as root !!! (use the --uid flag) *** 
*** WARNING: you are running uWSGI without its master process manager ***
your memory page size is 4096 bytes
detected max file descriptor number: 1048576
lock engine: pthread robust mutexes
thunder lock: disabled (you can enable it with --thunder-lock)
uwsgi socket 0 bound to TCP address 0.0.0.0:9201 fd 3
uWSGI running as root, you can use --uid/--gid/--chroot options
*** WARNING: you are running uWSGI as root !!! (use the --uid flag) *** 
Python version: 3.6.9 (default, Nov  7 2019, 10:44:02)  [GCC 8.3.0]
*** Python threads support is disabled. You can enable it with --enable-threads ***
Python main interpreter initialized at 0x564a8340a240
uWSGI running as root, you can use --uid/--gid/--chroot options
*** WARNING: you are running uWSGI as root !!! (use the --uid flag) *** 
your server socket listen backlog is limited to 100 connections
your mercy for graceful operations on workers is 60 seconds
mapped 72904 bytes (71 KB) for 1 cores
*** Operational MODE: single process ***
WSGI app 0 (mountpoint='') ready in 0 seconds on interpreter 0x564a8340a240 pid: 1 (default app)
uWSGI running as root, you can use --uid/--gid/--chroot options
*** WARNING: you are running uWSGI as root !!! (use the --uid flag) *** 
*** uWSGI is running in multiple interpreter mode ***
spawned uWSGI worker 1 (and the only) (pid: 1, cores: 1)
[pid: 1|app: 0|req: 1/1] 192.168.10.50 () {46 vars in 991 bytes} [Wed Apr  8 03:18:49 2020] GET / => generated 3407 bytes in 98 msecs (HTTP/1.1 200) 1 headers in 44 bytes (1 switches on core 0)
[pid: 1|app: 0|req: 2/2] 192.168.10.50 () {46 vars in 894 bytes} [Wed Apr  8 03:18:49 2020] GET /favicon.ico => generated 2154 bytes in 7 msecs (HTTP/1.1 200) 1 headers in 44 bytes (1 switches on core 0)
[pid: 1|app: 0|req: 3/3] 192.168.10.50 () {46 vars in 991 bytes} [Wed Apr  8 03:19:02 2020] GET / => generated 3966 bytes in 14 msecs (HTTP/1.1 200) 1 headers in 44 bytes (1 switches on core 0)
[pid: 1|app: 0|req: 4/4] 192.168.10.50 () {46 vars in 894 bytes} [Wed Apr  8 03:19:02 2020] GET /favicon.ico => generated 2154 bytes in 6 msecs (HTTP/1.1 200) 1 headers in 44 bytes (1 switches on core 0)
